Workbook

Sheet DISCLAIMER
C12: DISCLAIMER
C14: The content of this model is intended for discussion and illustrative purposes only.
C15: This model does not represent advice or a recommendation to enter into any investment and/or to make a financial decision.
C16: The viewers should consider obtaining independent professional advice before making any financial decisions.
P311: =$F311*P$5 -> 0

Sheet Guideline
B2: ='1. Project Summary'!B2 -> Projections - Serious Shea
B3: ='1. Project Summary'!B3 -> (in EUR, unless otherwise stated)
B5: General
B7: Introduction:
B8: This model provides an indicative 31-year financial forecast for Serious Shea's ARR project in Senegal (henceforth referred to as the "Project").
B9: The model includes the main costs for a VCS and CCB project.
B10: The net cash flows of the Project correspond to the net cash available to the project, after accounting for the main expenses including project development costs, ARR implementation costs, processing center costs, etc.
B11: The model does not account for taxes, and therefore, ignores the impact of tax losses carryforward, deferred tax assets, and deferred tax liabilities.
B12: The model ignores the impact of forex gains and losses.
B13: All financial figures are in EUR (unless stated otherwise).
B15: Formatting guideline:
B16: In black: formula-based cells.
B17: In blue: hard-coded inputs.
B18: In purple: key parameters but linked to other tabs.
... B127: This tab summarizes the output of EP Carbon's carbon accounting model. It is linked to the "4.1 Revenue Build - VCU" tab.
J280: =$F280*J$5 -> 0

Sheet 1. Project Summary
B2: ="Projections - "&Project_Name -> Projections - Serious Shea
B3: (in EUR, unless otherwise stated)
B5: Key Model Assumptions | E5: Unit | G5: Notes
B6: Project Info
C7: Project Name | F7: Serious Shea
C8: Location | F8: Senegal
C9: Project Start Date | E9: date | F9: 44927
C10: Project Validation Date | E10: date | F10: 45292
B12: Model assumptions
C13: Nominal or real terms | F13: Nominal | G13: Choose "Real" if the user would like to exclude the inflation impact.
C14: Discount rate | E14: % | F14: ='11.WACC'!D43 -> 0.135 | G14: Based on the proponent's estimated discount rate.
C15: Inflation rate | E15: % per annum | F15: =IF($F$13="Real",0,2%) -> 0.02 | G15: Based on the European Union's last 10-year average inflation rate as the cost and revenue estimates are in EUR.
C16: USD/EUR exchange rate | F16: =1.1015 -> 1.1015 | G16: Exchange rate as of April 27, 2023 by Bloomberg
B18: Revenue assumptions
C19: Carbon Credit Price
B20: 1 | C20: Scenario 1: Low Price | E20: EUR | F20: =8/F16 -> 7.2628234 | G20: Based on the similar project in Africa.
B21: 2 | C21: Scenario 2: Medium Price | E21: EUR | F21: 10 | G21: Based on the Proponent's expected pricing scenarios.
B22: 3 | C22: Scenario 3: High Price | E22: EUR | F22: =13.8/$F$16 -> 12.52837 | G22: Based on the lowest range of the ARR carbon prices published by Abatable
B23: 4 | C23: Scenario 4: Trove - Low Demand, Loose Supply | E23: EUR | F23: 9.9 | G23: Pricing scenario requested by Mirova. Source: Trove Intelligence
B24: 5 | C24: Scenario 5: Trove - High Demand, Loose Supply | E24: EUR | F24: 10.2 | G24: Pricing scenario requested by Mirova. Source: Trove Intelligence
B25: 6 | C25: Scenario 6: Trove - Low Demand,Tight Supply | E25: EUR | F25: 11.3 | G25: Pricing scenario requested by Mirova. Source: Trove Intelligence
B26: 7 | C26: Scenario 7: Trove - High Demand, Tight Supply | E26: EUR | F26: 11.9 | G26: Pricing scenario requested by Mirova. Source: Trove Intelligence
C28: User to Select Scenario for Carbon Credit Price | E28: EUR/VCU | F28: Scenario 2: Medium Price | G28: Choose the Carbon Credit Price Scenario here.
C29: Carbon Credit Price Increase | E29: % per annum | F29: =F15 -> 0.02 | G29: We assume that the carbon price will increase in-line with the inflation rate.
C31: Carbon Crediting Scenarios | F31: Total VCUs
B32: 1 | C32: Scenario 1: Low Crediting Scenario | E32: VCU | F32: ='4.1 Revenue Build - VCU'!E32 -> 6540628 | G32: These crediting scenarios originate from the carbon accounting model produced by EP Carbon.
B33: 2 | C33: Scenario 2: High Crediting Scenario | E33: VCU | F33: ='4.1 Revenue Build - VCU'!E33 -> 8089676
B34: 3 | C34: Scenario 3: Maximum Mitigation Potential | E34: VCU | F34: ='4.1 Revenue Build - VCU'!E34 -> 9753568
C36: User to Select Scenario for Carbon Crediting | F36: Scenario 2: High Crediting Scenario | G36: Choose the ARR VCU crediting scenario here.
B38: Cash Flow Summary | E38: Total | F38: Year 1-5 | G38: Year 6-10 | H38: Year 11-15 | I38: Year 16-20 | J38: Year 21-25 | K38: Year 26-31
B40: Cash Inflows
C41: ='2. NPV'!C9 -> Revenue from ARR | E41: =SUM(F41:K41) -> 1.123071e+08 | F41: =SUM('2. NPV'!H9:L9) -> 8435987.6 | G41: =SUM('2. NPV'!M9:Q9) -> 5848102.6 | H41: =SUM('2. NPV'!R9:V9) -> 19784719 | I41: =SUM('2. NPV'!W9:AA9) -> 21843928 | J41: =SUM('2. NPV'!AB9:AF9) -> 24117462 | K41: =SUM('2. NPV'!AG9:AL9) -> 32276901
C42: ='2. NPV'!C10 -> Revenue from Productive Activities | E42: =SUM(F42:K42) -> 7.7437181e+08 | F42: =SUM('2. NPV'!H10:L10) -> 31030346 | G42: =SUM('2. NPV'!M10:Q10) -> 1.0526043e+08 | H42: =SUM('2. NPV'!R10:V10) -> 1.2338335e+08 | I42: =SUM('2. NPV'!W10:AA10) -> 1.3959694e+08 | J42: =SUM('2. NPV'!AB10:AF10) -> 1.5794113e+08 | K42: =SUM('2. NPV'!AG10:AL10) -> 2.1715961e+08
C43: Grant Funding | E43: =SUM(F43:K43) -> 0 | F43: =SUM('2. NPV'!H11:L11) -> 0 | G43: =SUM('2. NPV'!M11:Q11) -> 0 | H43: =SUM('2. NPV'!R11:V11) -> 0 | I43: =SUM('2. NPV'!W11:AA11) -> 0 | J43: =SUM('2. NPV'!AB11:AF11) -> 0 | K43: =SUM('2. NPV'!AG11:AL11) -> 0
C44: Other Income | E44: =SUM(F44:K44) -> 0 | F44: =SUM('2. NPV'!H12:L12)+SUM('2. NPV'!H13:L13) -> 0 | G44: =SUM('2. NPV'!M13:Q13)+SUM('2. NPV'!M12:Q12) -> 0 | H44: =SUM('2. NPV'!R13:V13)+SUM('2. NPV'!R12:V12) -> 0 | I44: =SUM('2. NPV'!W13:AA13)+SUM('2. NPV'!W12:AA12) -> 0 | J44: =SUM('2. NPV'!AB13:AF13)+SUM('2. NPV'!AB12:AF12) -> 0 | K44: =SUM('2. NPV'!AG13:AL13)+SUM('2. NPV'!AG12:AL12) -> 0
B45: Total Cash Inflows | E45: =SUM(F45:L45) -> 8.8667891e+08 | F45: =SUM(F40:F44) -> 39466333 | G45: =SUM(G40:G44) -> 1.1110853e+08 | H45: =SUM(H40:H44) -> 1.4316807e+08 | I45: =SUM(I40:I44) -> 1.6144087e+08 | J45: =SUM(J40:J44) -> 1.8205859e+08 | K45: =SUM(K40:K44) -> 2.4943652e+08
B47: Cash Outflows
C48: Project Development Costs | E48: =SUM(F48:K48) -> 512173.4 | F48: =SUM('2. NPV'!H18:L18) -> 512173.4 | G48: =SUM('2. NPV'!M18:Q18) -> 0 | H48: =SUM('2. NPV'!R18:V18) -> 0 | I48: =SUM('2. NPV'!W18:AA18) -> 0 | J48: =SUM('2. NPV'!AB18:AF18) -> 0 | K48: =SUM('2. NPV'!AG18:AL18) -> 0
C49: Project Monitoring Costs | E49: =SUM(F49:K49) -> 5301107.4 | F49: =SUM('2. NPV'!H19:L19) -> 308221.78 | G49: =SUM('2. NPV'!M19:Q19) -> 722149.15 | H49: =SUM('2. NPV'!R19:V19) -> 859863.79 | I49: =SUM('2. NPV'!W19:AA19) -> 975798.49 | J49: =SUM('2. NPV'!AB19:AF19) -> 1021885.1 | K49: =SUM('2. NPV'!AG19:AL19) -> 1413189
C50: ARR Activity Costs | E50: =SUM(F50:K50) -> 71731731 | F50: =SUM('2. NPV'!H21:L26) -> 15122046 | G50: =SUM('2. NPV'!M21:Q26) -> 16547196 | H50: =SUM('2. NPV'!R21:V26) -> 8279448 | I50: =SUM('2. NPV'!W21:AA26) -> 8698429 | J50: =SUM('2. NPV'!AB21:AF26) -> 9758300.6 | K50: =SUM('2. NPV'!AG21:AL26) -> 13326312
...

Sheet 2. NPV
B2: ='1. Project Summary'!B2 -> Projections - Serious Shea
B3: ='1. Project Summary'!B3 -> (in EUR, unless otherwise stated)
B5: Net Present Value Calculations | D5: Unit | F5: Total | H5: =H47 -> 2024 | I5: =I47 -> 2025 | J5: =J47 -> 2026 | K5: =K47 -> 2027 | L5: =L47 -> 2028 | M5: =M47 -> 2029 | N5: =N47 -> 2030 | O5: =O47 -> 2031 | ... AL5: =AL47 -> 2054
F6: 2024-2054 | H6: Estimate | I6: Estimate | J6: Estimate | K6: Estimate | L6: Estimate | M6: Estimate | N6: Estimate | O6: Estimate | P6: Estimate | Q6: Estimate | R6: Estimate | S6: Estimate | T6: Estimate | U6: Estimate | V6: Estimate | W6: Estimate | X6: Estimate | Y6: Estimate | Z6: Estimate | AA6: Estimate | AB6: Estimate | AC6: Estimate | AD6: Estimate | AE6: Estimate | AF6: Estimate | AG6: Estimate | AH6: Estimate | AI6: Estimate | AJ6: Estimate | AK6: Estimate | AL6: Estimate
H7: =+'4.1 Revenue Build - VCU'!H$7 -> 1 | I7: =+'4.1 Revenue Build - VCU'!I$7 -> 2 | J7: =+'4.1 Revenue Build - VCU'!J$7 -> 3 | K7: =+'4.1 Revenue Build - VCU'!K$7 -> 4 | L7: =+'4.1 Revenue Build - VCU'!L$7 -> 5 | M7: =+'4.1 Revenue Build - VCU'!M$7 -> 6 | N7: =+'4.1 Revenue Build - VCU'!N$7 -> 7 | O7: =+'4.1 Revenue Build - VCU'!O$7 -> 8 | ... AL7: =+'4.1 Revenue Build - VCU'!AL$7 -> 31
C8: Cash Inflows
C9: Revenue from ARR | D9: EUR | F9: =SUM(H9:AL9) -> 1.123071e+08 | H9: ='4.1 Revenue Build - VCU'!H51 -> 3000000 | I9: ='4.1 Revenue Build - VCU'!I51 -> 2000000 | J9: ='4.1 Revenue Build - VCU'!J51 -> 2663550.9 | K9: ='4.1 Revenue Build - VCU'!K51 -> 609898.7 | L9: ='4.1 Revenue Build - VCU'!L51 -> 162538.01 | M9: ='4.1 Revenue Build - VCU'!M51 -> 366908.13 | N9: ='4.1 Revenue Build - VCU'!N51 -> 872190.27 | O9: ='4.1 Revenue Build - VCU'!O51 -> 754272.96 | ... AL9: ='4.1 Revenue Build - VCU'!AL51 -> 5649274.5
C10: Revenue from Productive Activities | D10: EUR | F10: =SUM(H10:AL10) -> 7.7437181e+08 | H10: ='4.2 Revenue Build - Other'!H40 -> 0 | I10: ='4.2 Revenue Build - Other'!I40 -> 640513.53 | J10: ='4.2 Revenue Build - Other'!J40 -> 6217535.7 | K10: ='4.2 Revenue Build - Other'!K40 -> 11217333 | L10: ='4.2 Revenue Build - Other'!L40 -> 12954963 | M10: ='4.2 Revenue Build - Other'!M40 -> 19267436 | N10: ='4.2 Revenue Build - Other'!N40 -> 20128254 | O10: ='4.2 Revenue Build - Other'!O40 -> 21020070 | ... AL10: ='4.2 Revenue Build - Other'!AL40 -> 38463729
C11: Grant Funding | D11: EUR | F11: =SUM(H11:AL11) -> 0
C12: Other income 1 | D12: EUR | F12: =SUM(H12:AL12) -> 0
C13: Other income 2 | D13: EUR | F13: =SUM(H13:AL13) -> 0
C14: Total Cash Inflows | F14: =SUM(H14:AL14) -> 8.8667891e+08 | H14: =SUM(H9:H13) -> 3000000 | I14: =SUM(I9:I13) -> 2640513.5 | J14: =SUM(J9:J13) -> 8881086.6 | K14: =SUM(K9:K13) -> 11827232 | L14: =SUM(L9:L13) -> 13117501 | M14: =SUM(M9:M13) -> 19634345 | N14: =SUM(N9:N13) -> 21000444 | O14: =SUM(O9:O13) -> 21774343 | ... AL14: =SUM(AL9:AL13) -> 44113003
C16: Cash Outflows
C17: Project Development and Monitoring Expenses
C18: Project Development Cost | D18: EUR | F18: =SUM(H18:AL18) -> 512173.4 | H18: ='5.1 Project Dev''t & Monitoring'!H24 -> 280980.48 | I18: ='5.1 Project Dev''t & Monitoring'!I24 -> 231192.92 | J18: ='5.1 Project Dev''t & Monitoring'!J24 -> 0 | K18: ='5.1 Project Dev''t & Monitoring'!K24 -> 0 | L18: ='5.1 Project Dev''t & Monitoring'!L24 -> 0 | M18: ='5.1 Project Dev''t & Monitoring'!M24 -> 0 | N18: ='5.1 Project Dev''t & Monitoring'!N24 -> 0 | O18: ='5.1 Project Dev''t & Monitoring'!O24 -> 0 | ... AL18: ='5.1 Project Dev''t & Monitoring'!AL24 -> 0
C19: Project Monitoring Cost | D19: EUR | F19: =SUM(H19:AL19) -> 5301107.4 | H19: ='5.1 Project Dev''t & Monitoring'!H57 -> 4167.0449 | I19: ='5.1 Project Dev''t & Monitoring'!I57 -> 66589.378 | J19: ='5.1 Project Dev''t & Monitoring'!J57 -> 60545.601 | K19: ='5.1 Project Dev''t & Monitoring'!K57 -> 91926.762 | L19: ='5.1 Project Dev''t & Monitoring'!L57 -> 84992.992 | M19: ='5.1 Project Dev''t & Monitoring'!M57 -> 119898.36 | N19: ='5.1 Project Dev''t & Monitoring'!N57 -> 114452.43 | O19: ='5.1 Project Dev''t & Monitoring'!O57 -> 170434.99 | ... AL19: ='5.1 Project Dev''t & Monitoring'!AL57 -> 225950.3
C20: ARR Costs
C21: ='5.2 Cost Build - ARR'!C134 -> Nursery - CAPEX | D21: EUR | F21: =SUM(H21:AL21) -> 1101992.1 | H21: ='5.2 Cost Build - ARR'!H134 -> 545540.62 | I21: ='5.2 Cost Build - ARR'!I134 -> 556451.44 | J21: ='5.2 Cost Build - ARR'!J134 -> 0 | K21: ='5.2 Cost Build - ARR'!K134 -> 0 | L21: ='5.2 Cost Build - ARR'!L134 -> 0 | M21: ='5.2 Cost Build - ARR'!M134 -> 0 | N21: ='5.2 Cost Build - ARR'!N134 -> 0 | O21: ='5.2 Cost Build - ARR'!O134 -> 0 | ... AL21: ='5.2 Cost Build - ARR'!AL134 -> 0
C22: ='5.2 Cost Build - ARR'!C135 -> Nursery - OPEX | D22: EUR | F22: =SUM(H22:AL22) -> 10716324 | H22: ='5.2 Cost Build - ARR'!H135 -> 816000 | I22: ='5.2 Cost Build - ARR'!I135 -> 1331712 | J22: ='5.2 Cost Build - ARR'!J135 -> 1358346.2 | K22: ='5.2 Cost Build - ARR'!K135 -> 1385513.2 | L22: ='5.2 Cost Build - ARR'!L135 -> 1413223.4 | M22: ='5.2 Cost Build - ARR'!M135 -> 1441487.9 | N22: ='5.2 Cost Build - ARR'!N135 -> 1470317.7 | O22: ='5.2 Cost Build - ARR'!O135 -> 1499724 | ... AL22: ='5.2 Cost Build - ARR'!AL135 -> 0
C23: ='5.2 Cost Build - ARR'!C136 -> Plantation & Transportation Cost | D23: EUR | F23: =SUM(H23:AL23) -> 5465325.4 | H23: ='5.2 Cost Build - ARR'!H136 -> 0 | I23: ='5.2 Cost Build - ARR'!I136 -> 416160 | J23: ='5.2 Cost Build - ARR'!J136 -> 679173.12 | K23: ='5.2 Cost Build - ARR'!K136 -> 692756.58 | L23: ='5.2 Cost Build - ARR'!L136 -> 706611.71 | M23: ='5.2 Cost Build - ARR'!M136 -> 720743.95 | N23: ='5.2 Cost Build - ARR'!N136 -> 735158.83 | O23: ='5.2 Cost Build - ARR'!O136 -> 749862 | ... AL23: ='5.2 Cost Build - ARR'!AL136 -> 0
C24: ='5.2 Cost Build - ARR'!C137 -> Maintenance cost | D24: EUR | F24: =SUM(H24:AL24) -> 3625378.3 | H24: ='5.2 Cost Build - ARR'!H137 -> 0 | I24: ='5.2 Cost Build - ARR'!I137 -> 0 | J24: ='5.2 Cost Build - ARR'!J137 -> 90202.68 | K24: ='5.2 Cost Build - ARR'!K137 -> 239217.51 | L24: ='5.2 Cost Build - ARR'!L137 -> 394156.85 | M24: ='5.2 Cost Build - ARR'!M137 -> 459474.27 | N24: ='5.2 Cost Build - ARR'!N137 -> 468663.75 | O24: ='5.2 Cost Build - ARR'!O137 -> 478037.03 | ... AL24: ='5.2 Cost Build - ARR'!AL137 -> 0
C25: ='5.2 Cost Build - ARR'!C138 -> Plantation Overhead | D25: EUR | F25: =SUM(H25:AL25) -> 43560757 | H25: ='5.2 Cost Build - ARR'!H138 -> 396060 | I25: ='5.2 Cost Build - ARR'!I138 -> 674967.48 | J25: ='5.2 Cost Build - ARR'!J138 -> 701931.74 | K25: ='5.2 Cost Build - ARR'!K138 -> 928306.66 | L25: ='5.2 Cost Build - ARR'!L138 -> 1044410.7 | M25: ='5.2 Cost Build - ARR'!M138 -> 1074613.7 | N25: ='5.2 Cost Build - ARR'!N138 -> 1188547.6 | O25: ='5.2 Cost Build - ARR'!O138 -> 1215202.8 | ... AL25: ='5.2 Cost Build - ARR'!AL138 -> 1969694.3
C26: ='5.2 Cost Build - ARR'!C144 -> Office Equipment & Vehicles | D26: EUR | F26: =SUM(H26:AL26) -> 7261954.5 | H26: ='5.2 Cost Build - ARR'!H144 -> 364670 | I26: ='5.2 Cost Build - ARR'!I144 -> 49894.2 | J26: ='5.2 Cost Build - ARR'!J144 -> 91166.85 | K26: ='5.2 Cost Build - ARR'!K144 -> 93337.474 | L26: ='5.2 Cost Build - ARR'!L144 -> 152235.78 | M26: ='5.2 Cost Build - ARR'!M144 -> 97863.138 | N26: ='5.2 Cost Build - ARR'!N144 -> 162697.69 | O26: ='5.2 Cost Build - ARR'!O144 -> 168248.03 | ... AL26: ='5.2 Cost Build - ARR'!AL144 -> 385438.51
C27: Productive Activity Costs
C28: ='5.3 Cost Build - Productive'!C128 -> Processing Centers - CAPEX | D28: EUR | F28: =SUM(H28:AL28) -> 8115482.1 | H28: ='5.3 Cost Build - Productive'!H128 -> 0 | I28: ='5.3 Cost Build - Productive'!I128 -> 735993.72 | J28: ='5.3 Cost Build - Productive'!J128 -> 772793.41 | K28: ='5.3 Cost Build - Productive'!K128 -> 811433.08 | L28: ='5.3 Cost Build - Productive'!L128 -> 852004.73 | M28: ='5.3 Cost Build - Productive'!M128 -> 894604.97 | N28: ='5.3 Cost Build - Productive'!N128 -> 939335.21 | O28: ='5.3 Cost Build - Productive'!O128 -> 986301.98 | ... AL28: ='5.3 Cost Build - Productive'!AL128 -> 0
C29: ='5.3 Cost Build - Productive'!C130 -> Processing Centers - OPEX | D29: EUR | F29: =SUM(H29:AL29) -> 50604091 | H29: ='5.3 Cost Build - Productive'!H130 -> 0 | I29: ='5.3 Cost Build - Productive'!I130 -> 97100.681 | J29: ='5.3 Cost Build - Productive'!J130 -> 407826.8 | K29: ='5.3 Cost Build - Productive'!K130 -> 691635.3 | L29: ='5.3 Cost Build - Productive'!L130 -> 814380.43 | M29: ='5.3 Cost Build - Productive'!M130 -> 1168019.3 | N29: ='5.3 Cost Build - Productive'!N130 -> 1251339.1 | O29: ='5.3 Cost Build - Productive'!O130 -> 1338590.6 | ... AL29: ='5.3 Cost Build - Productive'!AL130 -> 2572831
C30: ='5.3 Cost Build - Productive'!C131 -> Productive Activities' Overhead | D30: EUR | F30: =SUM(H30:AL30) -> 57052660 | H30: ='5.3 Cost Build - Productive'!H131 -> 22740 | I30: ='5.3 Cost Build - Productive'!I131 -> 181609.8 | J30: ='5.3 Cost Build - Productive'!J131 -> 392907.97 | K30: ='5.3 Cost Build - Productive'!K131 -> 568939.19 | L30: ='5.3 Cost Build - Productive'!L131 -> 762870.12 | M30: ='5.3 Cost Build - Productive'!M131 -> 959745.18 | N30: ='5.3 Cost Build - Productive'!N131 -> 1163276.5 | O30: ='5.3 Cost Build - Productive'!O131 -> 1373376.8 | ... AL30: ='5.3 Cost Build - Productive'!AL131 -> 2799261.6
C31: ='5.2 Cost Build - ARR'!C144 -> Office Equipment & Vehicles | D31: EUR | F31: =SUM(H31:AL31) -> 11525667 | H31: ='5.3 Cost Build - Productive'!H136 -> 206162 | I31: ='5.3 Cost Build - Productive'!I136 -> 196747.2 | J31: ='5.3 Cost Build - Productive'!J136 -> 219663.23 | K31: ='5.3 Cost Build - Productive'!K136 -> 212068.12 | L31: ='5.3 Cost Build - Productive'!L136 -> 231569.44 | M31: ='5.3 Cost Build - Productive'!M136 -> 228763.68 | N31: ='5.3 Cost Build - Productive'!N136 -> 243915.52 | O31: ='5.3 Cost Build - Productive'!O136 -> 252214.78 | ... AL31: ='5.3 Cost Build - Productive'!AL136 -> 643344.37
C32: Increase in Net Working Capital | D32: EUR | F32: =SUM(H32:AL32) -> 9306349.9 | H32: =-'7.CFS'!H13 -> -5589.0411 | I32: =-'7.CFS'!I13 -> 105077.16 | J32: =-'7.CFS'!J13 -> 1457551.4 | K32: =-'7.CFS'!K13 -> 1295934.9 | L32: =-'7.CFS'!L13 -> 398588.24 | M32: =-'7.CFS'!M13 -> 1648233.4 | N32: =-'7.CFS'!N13 -> 150754.39 | O32: =-'7.CFS'!O13 -> 155229.49 | ... AL32: =-'7.CFS'!AL13 -> 226984.15
C33: Other expenses 1 | D33: EUR | F33: =SUM(H33:AL33) -> 0
C34: Other expenses 2 | D34: EUR | F34: =SUM(H34:AL34) -> 0
C35: Other expenses 3 | D35: EUR | F35: =SUM(H35:AL35) -> 0
C36: Total Cash Outflows | F36: =SUM(F17:F35) -> 2.1414926e+08 | H36: =SUM(H17:H35) -> 2630731.1 | I36: =SUM(I17:I35) -> 4643496 | J36: =SUM(J17:J35) -> 6232109.1 | K36: =SUM(K17:K35) -> 7011068.7 | L36: =SUM(L17:L35) -> 6855044.4 | M36: =SUM(M17:M35) -> 8813447.8 | N36: =SUM(N17:N35) -> 7888458.6 | O36: =SUM(O17:O35) -> 8387222.4 | ... AL36: =SUM(AL17:AL35) -> 8823504.2
C38: Net Cash Flow in Period | D38: EUR | F38: =SUM(H38:AL38) -> 6.7252965e+08 | H38: =H14-H36 -> 369268.89 | I38: =I14-I36 -> -2002982.4 | J38: =J14-J36 -> 2648977.5 | K38: =K14-K36 -> 4816162.9 | L38: =L14-L36 -> 6262457 | M38: =M14-M36 -> 10820897 | N38: =N14-N36 -> 13111985 | O38: =O14-O36 -> 13387120 | ... AL38: =AL14-AL36 -> 35289499
C39: Beginning Cash Balance | D39: EUR | H39: =G40 -> 0 | I39: =H40 -> 369268.89 | J39: =I40 -> -1633713.6 | K39: =J40 -> 1015263.9 | L39: =K40 -> 5831426.8 | M39: =L40 -> 12093884 | N39: =M40 -> 22914781 | O39: =N40 -> 36026766 | ... AL39: =AK40 -> 6.3724015e+08
C40: Ending Cash Balance | D40: EUR | G40: 0 | H40: =H38+H39 -> 369268.89 | I40: =I38+I39 -> -1633713.6 | J40: =J38+J39 -> 1015263.9 | K40: =K38+K39 -> 5831426.8 | L40: =L38+L39 -> 12093884 | M40: =M38+M39 -> 22914781 | N40: =N38+N39 -> 36026766 | O40: =O38+O39 -> 49413886 | ... AL40: =AL38+AL39 -> 6.7252965e+08
C43: Project Returns | D43: Unit
C44: NPV Date | D44: date | E44: 44927
C45: Discount Rate | D45: % | E45: ='1. Project Summary'!$F$14 -> 0.135
C47: Year | D47: year | H47: 2024 | I47: =H47+1 -> 2025 | J47: =I47+1 -> 2026 | K47: =J47+1 -> 2027 | L47: =K47+1 -> 2028 | M47: =L47+1 -> 2029 | N47: =M47+1 -> 2030 | O47: =N47+1 -> 2031 | P47: =O47+1 -> 2032 | ... AL47: =AK47+1 -> 2054
...

Sheet 3. Assumptions
B2: ='1. Project Summary'!B2 -> Projections - Serious Shea
B3: ='1. Project Summary'!B3 -> (in EUR, unless otherwise stated)
B5: Revenue Assumptions | D5: Unit
B7: Revenues from Productive Activities | E7: Price | F7: Price CAGR | G7: Revenue Attributable to Serious Shea
B8: 1 | C8: Refined Oil | D8: EUR per metric ton | E8: 30000 | F8: 0.025 | G8: 1 | I8: Based on the benchmark price discounted to ~60-70%
B9: 2 | C9: Moringa Leaves | D9: EUR per metric ton | E9: 5000 | F9: 0.025 | G9: 1 | I9: Based on the benchmark price discounted to ~60-70%
B10: 3 | C10: Dry Mangos | D10: EUR per metric ton | E10: 3500 | F10: 0.025 | G10: 0.3 | I10: Based on the benchmark price discounted to ~60-70%
B11: 4 | C11: Shea Butter | D11: EUR per metric ton | E11: 2000 | F11: 0.025 | G11: 0.3 | I11: Based on the benchmark price discounted to ~60-70%
B12: 5 | C12: Fertilisers Compost | D12: EUR per metric ton | E12: 100 | F12: 0.025 | G12: 1 | I12: Based on the benchmark price discounted to ~20%
B13: 6 | C13: Biochar | D13: EUR per metric ton
B15: Revenue from Processing Fee
B16: 3 | C16: Dry Mangos | D16: EUR per metric ton | E16: 100 | F16: 0.025
B17: 4 | C17: Shea Butter | D17: EUR per metric ton | E17: 200 | F17: 0.025
B19: Cost Inputs/Assumptions | D19: Unit
B20: 5.1 Project Development & Monitoring
B21: Timing Assumptions
C22: First Year of Credit Issuance | D22: years | F22: 3 | G22: The model assumes the First Year of Credit Issuance will happen in 2025.
C23: Interval between Credit Issuances/Sales after First Issuance | D23: years | F23: 1 | G23: The Projects assumes that verifications and credit issuances will take place in the same years. This can be changed to 2 years depending on the sales & marketing strategy.
C24: Year of Validation | D24: years | F24: 2 | G24: The typical timeline that we see for project development from Feasibility Assessment to Validation is 12-18 months. We assume that the Project will be validated in 2024.
C25: First Verification Year | D25: years | F25: 2 | G25: Same time as validation.
C26: Verification Interval Thereafter | D26: years | F26: 2
C27: Frequency of Revisions | D27: years | F27: 6 | G27: The baseline revision is subject to changes by Verra. We assume it will happen every 6 years based on its existing guideline.
B29: Project Development Work
C30: Feasibility assessment | D30: USD | F30: 73250 | G30: Feasibility Assessment Fee to EP Carbon | H30: Low | I30: High
C31: Work plan | D31: USD | F31: =AVERAGE(H31:I31) -> 5000 | H31: 0 | I31: 10000 | J31: Provisional estimates included in the Feasibility Assessment proposal
C32: Project Description Document | D32: USD | F32: =AVERAGE(H32:I32) -> 200000 | H32: =250000-H34 -> 170000 | I32: =350000-I34 -> 230000 | J32: Provisional estimates included in the Feasibility Assessment proposal
C33: Audit support to issuance | D33: USD | F33: =AVERAGE(H33:I33) -> 62500 | H33: 50000 | I33: 75000 | J33: Provisional estimates included in the Feasibility Assessment proposal
C34: First MIR | D34: USD | F34: =AVERAGE(H34:I34) -> 100000 | H34: 80000 | I34: 120000 | J34: Provisional estimates included in the Feasibility Assessment proposal (PDD + MIR ranges between US$250k and US$350k)
C35: VCS + CCB Validation | D35: USD | F35: 22500 | G35: Estimated fee to VCS for the assessment of the Project's conformance to VCS rules and applied methodology. CCB Validation is US$2,500 per CCB Standards Fee Schedule v3.4.
C36: Additional costs for CCB | D36: USD | F36: 100000 | G36: EP Carbon estimate.
B38: Project Monitoring Work
C39: Verra Registry Account Opening Fee VCS | D39: USD | F39: 500 | G39: VCS Program Fee Schedule v4.3 | I39: https://verra.org/wp-content/uploads/2023/03/Program-Fee-Schedule-v4.3-FINAL.pdf
C40: VCS Account maintenance fee | D40: USD per annum | F40: 500 | G40: VCS Program Fee Schedule v4.3
C41: VCS Pipeline Listing request fee | D41: USD | F41: 1000 | G41: VCS Program Fee Schedule v4.3
C42: VCS Project registeration request review fee | D42: USD | F42: 2500 | G42: VCS Program Fee Schedule v4.3
C43: VCU Issuance levy | D43: USD per VCU | F43: 0.2 | G43: VCS Program Fee Schedule v4.3
C44: CCB Label fee | D44: USD per label | F44: 0.07 | G44: CCB Program Fee Schedule v3.5 | I44: https://verra.org/wp-content/uploads/2023/03/CCB-Standards-Fee-Schedule-v3.5-final.pdf
C45: CCB Account maintenance fee | D45: USD | F45: 500 | G45: CCB Program Fee Schedule v3.5
C46: VCS Verification | D46: USD | F46: 15000 | G46: EP Carbon estimate for the verification audit and audit preparation
C47: CCB Verification | D47: USD | F47: 5000 | G47: CCB Program Fee Schedule v3.5 | I47: For each application for CCB certfication
...

Sheet 4.1 Revenue Build - VCU
B2: ='1. Project Summary'!B2 -> Projections - Serious Shea
B3: ='1. Project Summary'!B3 -> (in EUR, unless otherwise stated)
B5: Revenue Build | D5: Unit | H5: ='2. NPV'!H5 -> 2024 | I5: ='2. NPV'!I5 -> 2025 | J5: ='2. NPV'!J5 -> 2026 | K5: ='2. NPV'!K5 -> 2027 | L5: ='2. NPV'!L5 -> 2028 | M5: ='2. NPV'!M5 -> 2029 | N5: ='2. NPV'!N5 -> 2030 | O5: ='2. NPV'!O5 -> 2031 | ... AL5: ='2. NPV'!AL5 -> 2054
H6: =Period_Start -> 1 | I6: =H6+1 -> 2 | J6: =I6+1 -> 3 | K6: =J6+1 -> 4 | L6: =K6+1 -> 5 | M6: =L6+1 -> 6 | N6: =M6+1 -> 7 | O6: =N6+1 -> 8 | P6: =O6+1 -> 9 | ... AL6: =AK6+1 -> 31
C7: Year count | H7: 1 | I7: =+H7+1 -> 2 | J7: =+I7+1 -> 3 | K7: =+J7+1 -> 4 | L7: =+K7+1 -> 5 | M7: =+L7+1 -> 6 | N7: =+M7+1 -> 7 | O7: =+N7+1 -> 8 | P7: =+O7+1 -> 9 | ... AL7: =+AK7+1 -> 31
C8: Credit Issuance Dates
C9: First Year of Credit Issuance | D9: year | E9: ='3. Assumptions'!F22 -> 3
C10: Interval between Credit Issuances | D10: year | E10: ='3. Assumptions'!F23 -> 1
C11: Year for Flag Credit Issuance | H11: =IF('4.1 Revenue Build - VCU'!H$6=34,1,IF('4.1 Revenue Build - VCU'!H6<'4.1 Revenue Build - VCU'!$E$9,0,IF('4.1 Revenue Build - VCU'!H6='4.1 Revenue Build - VCU'!$E$9,1,IF(MOD('4.1 Revenue Build - VCU'!H$6-'4.1 Revenue Build - VCU'!$E$9,'4.1 Revenue Build - VCU'!$E$10)=0,1,0)))) -> 0 | I11: =IF('4.1 Revenue Build - VCU'!I$6=34,1,IF('4.1 Revenue Build - VCU'!I6<'4.1 Revenue Build - VCU'!$E$9,0,IF('4.1 Revenue Build - VCU'!I6='4.1 Revenue Build - VCU'!$E$9,1,IF(MOD('4.1 Revenue Build - VCU'!I$6-'4.1 Revenue Build - VCU'!$E$9,'4.1 Revenue Build - VCU'!$E$10)=0,1,0)))) -> 0 | J11: =IF('4.1 Revenue Build - VCU'!J$6=34,1,IF('4.1 Revenue Build - VCU'!J6<'4.1 Revenue Build - VCU'!$E$9,0,IF('4.1 Revenue Build - VCU'!J6='4.1 Revenue Build - VCU'!$E$9,1,IF(MOD('4.1 Revenue Build - VCU'!J$6-'4.1 Revenue Build - VCU'!$E$9,'4.1 Revenue Build - VCU'!$E$10)=0,1,0)))) -> 1 | K11: =IF('4.1 Revenue Build - VCU'!K$6=34,1,IF('4.1 Revenue Build - VCU'!K6<'4.1 Revenue Build - VCU'!$E$9,0,IF('4.1 Revenue Build - VCU'!K6='4.1 Revenue Build - VCU'!$E$9,1,IF(MOD('4.1 Revenue Build - VCU'!K$6-'4.1 Revenue Build - VCU'!$E$9,'4.1 Revenue Build - VCU'!$E$10)=0,1,0)))) -> 1 | L11: =IF('4.1 Revenue Build - VCU'!L$6=34,1,IF('4.1 Revenue Build - VCU'!L6<'4.1 Revenue Build - VCU'!$E$9,0,IF('4.1 Revenue Build - VCU'!L6='4.1 Revenue Build - VCU'!$E$9,1,IF(MOD('4.1 Revenue Build - VCU'!L$6-'4.1 Revenue Build - VCU'!$E$9,'4.1 Revenue Build - VCU'!$E$10)=0,1,0)))) -> 1 | M11: =IF('4.1 Revenue Build - VCU'!M$6=34,1,IF('4.1 Revenue Build - VCU'!M6<'4.1 Revenue Build - VCU'!$E$9,0,IF('4.1 Revenue Build - VCU'!M6='4.1 Revenue Build - VCU'!$E$9,1,IF(MOD('4.1 Revenue Build - VCU'!M$6-'4.1 Revenue Build - VCU'!$E$9,'4.1 Revenue Build - VCU'!$E$10)=0,1,0)))) -> 1 | N11: =IF('4.1 Revenue Build - VCU'!N$6=34,1,IF('4.1 Revenue Build - VCU'!N6<'4.1 Revenue Build - VCU'!$E$9,0,IF('4.1 Revenue Build - VCU'!N6='4.1 Revenue Build - VCU'!$E$9,1,IF(MOD('4.1 Revenue Build - VCU'!N$6-'4.1 Revenue Build - VCU'!$E$9,'4.1 Revenue Build - VCU'!$E$10)=0,1,0)))) -> 1 | O11: =IF('4.1 Revenue Build - VCU'!O$6=34,1,IF('4.1 Revenue Build - VCU'!O6<'4.1 Revenue Build - VCU'!$E$9,0,IF('4.1 Revenue Build - VCU'!O6='4.1 Revenue Build - VCU'!$E$9,1,IF(MOD('4.1 Revenue Build - VCU'!O$6-'4.1 Revenue Build - VCU'!$E$9,'4.1 Revenue Build - VCU'!$E$10)=0,1,0)))) -> 1 | ... AL11: =IF('4.1 Revenue Build - VCU'!AL$6=34,1,IF('4.1 Revenue Build - VCU'!AL6<'4.1 Revenue Build - VCU'!$E$9,0,IF('4.1 Revenue Build - VCU'!AL6='4.1 Revenue Build - VCU'!$E$9,1,IF(MOD('4.1 Revenue Build - VCU'!AL$6-'4.1 Revenue Build - VCU'!$E$9,'4.1 Revenue Build - VCU'!$E$10)=0,1,0)))) -> 1
C13: Credit Price Escalation | D13: % | E13: ='1. Project Summary'!F29 -> 0.02 | H13: 0 | I13: =E13 -> 0.02 | J13: =I13 -> 0.02 | K13: =J13 -> 0.02 | L13: =K13 -> 0.02 | M13: =L13 -> 0.02 | N13: =M13 -> 0.02 | O13: =N13 -> 0.02 | P13: =O13 -> 0.02 | Q13: =P13 -> 0.02 | ... AL13: =AK13 -> 0.02
C15: ARR
C17: Carbon Price Scenario Chosen | D17: =MATCH(E17,C20:C26,0) -> 2 | E17: ='1. Project Summary'!F28 -> Scenario 2: Medium Price
C19: Carbon Credit Price
B20: 1 | C20: ='1. Project Summary'!C20 -> Scenario 1: Low Price | D20: EUR | E20: ='1. Project Summary'!F20 -> 7.2628234 | H20: =$E20*(1+H13) -> 7.2628234 | I20: =H20*(1+I$13) -> 7.4080799 | J20: =I20*(1+J$13) -> 7.5562415 | K20: =J20*(1+K$13) -> 7.7073663 | L20: =K20*(1+L$13) -> 7.8615136 | M20: =L20*(1+M$13) -> 8.0187439 | N20: =M20*(1+N$13) -> 8.1791188 | O20: =N20*(1+O$13) -> 8.3427012 | P20: =O20*(1+P$13) -> 8.5095552 | ... AL20: =AK20*(1+AL$13) -> 13.155599
B21: 2 | C21: ='1. Project Summary'!C21 -> Scenario 2: Medium Price | D21: EUR | E21: ='1. Project Summary'!F21 -> 10 | H21: =$E21*(1+H13) -> 10 | I21: =H21*(1+I$13) -> 10.2 | J21: =I21*(1+J$13) -> 10.404 | K21: =J21*(1+K$13) -> 10.61208 | L21: =K21*(1+L$13) -> 10.824322 | M21: =L21*(1+M$13) -> 11.040808 | N21: =M21*(1+N$13) -> 11.261624 | O21: =N21*(1+O$13) -> 11.486857 | P21: =O21*(1+P$13) -> 11.716594 | ... AL21: =AK21*(1+AL$13) -> 18.113616
B22: 3 | C22: ='1. Project Summary'!C22 -> Scenario 3: High Price | D22: EUR | E22: ='1. Project Summary'!F22 -> 12.52837 | H22: =$E22*(1+H13) -> 12.52837 | I22: =H22*(1+I$13) -> 12.778938 | J22: =I22*(1+J$13) -> 13.034517 | K22: =J22*(1+K$13) -> 13.295207 | L22: =K22*(1+L$13) -> 13.561111 | M22: =L22*(1+M$13) -> 13.832333 | N22: =M22*(1+N$13) -> 14.10898 | O22: =N22*(1+O$13) -> 14.39116 | P22: =O22*(1+P$13) -> 14.678983 | ... AL22: =AK22*(1+AL$13) -> 22.693409
B23: 4 | C23: Scenario 4: Trove - Low Demand, Loose Supply | E23: ='1. Project Summary'!F23 -> 9.9 | H23: =E23 -> 9.9 | I23: 6.6778877 | J23: 7.4881851 | K23: 8.5998389 | L23: 9.8261279 | M23: 10.948756 | N23: 12.073852 | O23: 13.100757 | P23: 13.916354 | Q23: 14.62504 | R23: 15.736281 | S23: 16.806204 | T23: 18.268082 | U23: 19.801796 | V23: 21.33551 | W23: 22.80098 | X23: 24.144327 | Y23: 25.397878 | Z23: 26.525714 | AA23: 27.473959 | AB23: 28.267755 | AC23: 28.896327 | AD23: 29.381224 | AE23: 29.740408 | AF23: 29.955918 | AG23: 30.063673 | AH23: 30.13551 | AI23: 30.171429 | AJ23: =AI23 -> 30.171429 | AK23: =AJ23 -> 30.171429 | AL23: =AK23 -> 30.171429
B24: 5 | C24: Scenario 5: Trove - High Demand, Loose Supply | E24: ='1. Project Summary'!F24 -> 10.2 | H24: =E24 -> 10.2 | I24: 9.834449 | J24: 11.720163 | K24: 13.516082 | L24: 15.254531 | M24: 16.99298 | N24: 18.867918 | O24: 21.033796 | P24: 23.555265 | Q24: 26.371265 | R24: 29.402776 | S24: 32.373224 | T24: 35.156898 | U24: 37.76098 | V24: 40.199837 | W24: 42.401633 | X24: 44.423837 | Y24: 46.413714 | Z24: 48.4 | AA24: 50.314449 | AB24: 52.178612 | AC24: 53.970939 | AD24: 55.583673 | AE24: 56.912653 | AF24: 57.900408 | AG24: 58.564898 | AH24: 58.942041 | AI24: 59.139592 | AJ24: =AI24 -> 59.139592 | AK24: =AJ24 -> 59.139592 | AL24: =AK24 -> 59.139592
B25: 6 | C25: Scenario 6: Trove - Low Demand,Tight Supply | E25: ='1. Project Summary'!F25 -> 11.3 | H25: =E25 -> 11.3 | I25: 8.3837786 | J25: 9.4336044 | K25: 10.879176 | L25: 12.514144 | M25: 14.18452 | N25: 15.8752 | O25: 17.446579 | P25: 18.712371 | Q25: 19.700089 | R25: 21.077346 | S25: 22.25502 | T25: 23.864163 | U25: 25.387102 | V25: 26.787918 | W25: 28.001959 | X25: 29.057959 | Y25: 30.042122 | Z25: 31.040653 | AA25: 32.11102 | AB25: 33.264 | AC25: 34.485224 | AD25: 35.710041 | AE25: 36.830694 | AF25: 37.70351 | AG25: 38.28898 | AH25: 38.662531 | AI25: 38.852898 | AJ25: =AI25 -> 38.852898 | AK25: =AJ25 -> 38.852898 | AL25: =AK25 -> 38.852898
B26: 7 | C26: Scenario 7: Trove - High Demand, Tight Supply | E26: ='1. Project Summary'!F26 -> 11.9 | H26: =E26 -> 11.9 | I26: 12.266122 | J26: 14.672653 | K26: 17.043265 | L26: 19.338449 | M26: 21.597714 | N26: 23.821061 | O26: 26.403592 | P26: 29.370449 | Q26: 32.807837 | R26: 36.708571 | S26: 40.896653 | T26: 45.19249 | U26: 49.430857 | V26: 53.457306 | W26: 56.937796 | X26: 59.804082 | Y26: 62.023837 | Z26: 63.701224 | AA26: 64.940408 | AB26: 65.949714 | AC26: 66.937469 | AD26: 67.971918 | AE26: 69.078204 | AF26: 70.116245 | AG26: 70.963918 | AH26: 71.585306 | AI26: 71.980408 | AJ26: =AI26 -> 71.980408 | AK26: =AJ26 -> 71.980408 | AL26: =AK26 -> 71.980408
C27: Applicable Credit Price | E27: =H27 -> 10 | H27: =CHOOSE($D$17,H20,H21,H22,H23,H24,H25,H26) -> 10 | I27: =CHOOSE($D$17,I20,I21,I22,I23,I24,I25,I26) -> 10.2 | J27: =CHOOSE($D$17,J20,J21,J22,J23,J24,J25,J26) -> 10.404 | K27: =CHOOSE($D$17,K20,K21,K22,K23,K24,K25,K26) -> 10.61208 | L27: =CHOOSE($D$17,L20,L21,L22,L23,L24,L25,L26) -> 10.824322 | M27: =CHOOSE($D$17,M20,M21,M22,M23,M24,M25,M26) -> 11.040808 | N27: =CHOOSE($D$17,N20,N21,N22,N23,N24,N25,N26) -> 11.261624 | O27: =CHOOSE($D$17,O20,O21,O22,O23,O24,O25,O26) -> 11.486857 | ... AL27: =CHOOSE($D$17,AL20,AL21,AL22,AL23,AL24,AL25,AL26) -> 18.113616
C29: Carbon Crediting Scenario Chosen | D29: =MATCH(E29,C32:C34,0) -> 2 | E29: ='1. Project Summary'!F36 -> Scenario 2: High Crediting Scenario
C31: Carbon Crediting Scenarios | E31: Total VCUs
B32: 1 | C32: ='1. Project Summary'!C32 -> Scenario 1: Low Crediting Scenario | D32: VCU | E32: =SUM(H32:AL32) -> 6540628 | H32: ='12. VCU Volume'!E41 -> 0 | I32: ='12. VCU Volume'!F41 -> 1640 | J32: ='12. VCU Volume'!G41 -> 35324 | K32: ='12. VCU Volume'!H41 -> 69008 | L32: ='12. VCU Volume'!I41 -> 102696 | M32: ='12. VCU Volume'!J41 -> 140060 | N32: ='12. VCU Volume'!K41 -> 177428 | O32: ='12. VCU Volume'!L41 -> 214792 | ... AL32: ='12. VCU Volume'!AI41 -> 252160
B33: 2 | C33: ='1. Project Summary'!C33 -> Scenario 2: High Crediting Scenario | D33: VCU | E33: =SUM(H33:AL33) -> 8089676 | H33: ='12. VCU Volume'!E42 -> 0 | I33: ='12. VCU Volume'!F42 -> 2028 | J33: ='12. VCU Volume'!G42 -> 43692 | K33: ='12. VCU Volume'!H42 -> 85356 | L33: ='12. VCU Volume'!I42 -> 127016 | M33: ='12. VCU Volume'!J42 -> 173232 | N33: ='12. VCU Volume'!K42 -> 219448 | O33: ='12. VCU Volume'!L42 -> 265664 | ... AL33: ='12. VCU Volume'!AI42 -> 311880
B34: 3 | C34: ='1. Project Summary'!C34 -> Scenario 3: Maximum Mitigation Potential | D34: VCU | E34: =SUM(H34:AL34) -> 9753568 | H34: ='12. VCU Volume'!E43 -> 0 | I34: ='12. VCU Volume'!F43 -> 2448 | J34: ='12. VCU Volume'!G43 -> 52676 | K34: ='12. VCU Volume'!H43 -> 102908 | L34: ='12. VCU Volume'!I43 -> 153140 | M34: ='12. VCU Volume'!J43 -> 208864 | N34: ='12. VCU Volume'!K43 -> 264584 | O34: ='12. VCU Volume'!L43 -> 320304 | ... AL34: ='12. VCU Volume'!AI43 -> 376028
C36: Applicable Credit Volume | D36: VCU | E36: =SUM(H36:AL36) -> 8089676 | H36: =CHOOSE($D$29,H32,H33,H34) -> 0 | I36: =CHOOSE($D$29,I32,I33,I34) -> 2028 | J36: =CHOOSE($D$29,J32,J33,J34) -> 43692 | K36: =CHOOSE($D$29,K32,K33,K34) -> 85356 | L36: =CHOOSE($D$29,L32,L33,L34) -> 127016 | M36: =CHOOSE($D$29,M32,M33,M34) -> 173232 | N36: =CHOOSE($D$29,N32,N33,N34) -> 219448 | O36: =CHOOSE($D$29,O32,O33,O34) -> 265664 | ... AL36: =CHOOSE($D$29,AL32,AL33,AL34) -> 311880
C38: Cummulative VCUs | D38: VCU | H38: =SUM($H$36:H$36) -> 0 | I38: =SUM($H$36:I$36) -> 2028 | J38: =SUM($H$36:J$36) -> 45720 | K38: =SUM($H$36:K$36) -> 131076 | L38: =SUM($H$36:L$36) -> 258092 | M38: =SUM($H$36:M$36) -> 431324 | N38: =SUM($H$36:N$36) -> 650772 | O38: =SUM($H$36:O$36) -> 916436 | ... AL38: =SUM($H$36:AL$36) -> 8089676
C39: VCUs to be issued | D39: VCU | E39: =SUM(H39:AL39) -> 8089676 | H39: =IF(H$11=0,0,H$38-SUM(#REF!)) -> 0 | I39: =IF(I$11=0,0,I$38-SUM($H39:H$39)) -> 0 | J39: =IF(J$11=0,0,J$38-SUM($H39:I$39)) -> 45720 | K39: =IF(K$11=0,0,K$38-SUM($H39:J$39)) -> 85356 | L39: =IF(L$11=0,0,L$38-SUM($H39:K$39)) -> 127016 | M39: =IF(M$11=0,0,M$38-SUM($H39:L$39)) -> 173232 | N39: =IF(N$11=0,0,N$38-SUM($H39:M$39)) -> 219448 | O39: =IF(O$11=0,0,O$38-SUM($H39:N$39)) -> 265664 | P39: =IF(P$11=0,0,P$38-SUM($H39:O$39)) -> 311880 | ... AL39: =IF(AL$11=0,0,AL$38-SUM($H39:AK$39)) -> 311880
C40: VCUs attributable to Mirova | D40: VCU | E40: =SUM(J40:AL40) -> 1000000 | J40: =MIN(OFFSET(J$54,$E$10,0),J39) -> 30000 | K40: =MIN(OFFSET(K$54,$E$10,0),K39) -> 75000 | L40: =MIN(OFFSET(L$54,$E$10,0),L39) -> 112000 | M40: =MIN(OFFSET(M$54,$E$10,0),M39) -> 140000 | N40: =MIN(OFFSET(N$54,$E$10,0),N39) -> 142000 | O40: =MIN(OFFSET(O$54,$E$10,0),O39) -> 200000 | P40: =MIN(OFFSET(P$54,$E$10,0),P39) -> 301000 | Q40: =IF(Q38>1000000,1000000-SUM($H40:P40),Q39)*Q11 -> 0 | R40: =IF(R38>1000000,1000000-SUM($H40:Q40),R39)*R11 -> 0 | S40: =IF(S38>1000000,1000000-SUM($H40:R40),S39)*S11 -> 0 | T40: =IF(T38>1000000,1000000-SUM($H40:S40),T39)*T11 -> 0 | U40: =IF(U38<1000000,U39,0) -> 0 | V40: =IF(V38<1000000,V39,0) -> 0
C41: VCUs attributable to Others | D41: VCU | E41: =SUM(H41:AL41) -> 7089676 | H41: =H39-H40 -> 0 | I41: =I39-I40 -> 0 | J41: =J39-J40 -> 15720 | K41: =K39-K40 -> 10356 | L41: =L39-L40 -> 15016 | M41: =M39-M40 -> 33232 | N41: =N39-N40 -> 77448 | O41: =O39-O40 -> 65664 | ... AL41: =AL39-AL40 -> 311880
C43: ARR Revenue (to be recognized)
C44: Revenue attributable to Mirova | D44: EUR | E44: =SUM(H44:AL44) -> 10000000 | H44: =H40*$E$21 -> 0 | I44: =I40*$E$21 -> 0 | J44: =J40*$E$21 -> 300000 | K44: =K40*$E$21 -> 750000 | L44: =L40*$E$21 -> 1120000 | M44: =M40*$E$21 -> 1400000 | N44: =N40*$E$21 -> 1420000 | O44: =O40*$E$21 -> 2000000 | ... AL44: =AL40*$E$21 -> 0
C45: Revenue attributable to Others | D45: EUR | E45: =SUM(H45:AL45) -> 1.043071e+08 | H45: =H41*H27 -> 0 | I45: =I41*I27 -> 0 | J45: =J41*J27 -> 163550.88 | K45: =K41*K27 -> 109898.7 | L45: =L41*L27 -> 162538.01 | M45: =M41*M27 -> 366908.13 | N45: =N41*N27 -> 872190.27 | O45: =O41*O27 -> 754272.96 | ... AL45: =AL41*AL27 -> 5649274.5
C46: ARR Revenue | D46: EUR | E46: =SUM(H46:AK46) -> 1.0865783e+08 | H46: =SUM(H44:H45) -> 0 | I46: =SUM(I44:I45) -> 0 | J46: =SUM(J44:J45) -> 463550.88 | K46: =SUM(K44:K45) -> 859898.7 | L46: =SUM(L44:L45) -> 1282538 | M46: =SUM(M44:M45) -> 1766908.1 | N46: =SUM(N44:N45) -> 2292190.3 | O46: =SUM(O44:O45) -> 2754273 | ... AL46: =SUM(AL44:AL45) -> 5649274.5
C48: ARR Revenue (cash based)
C49: Prepayment from Mirova | D49: EUR | E49: =SUM(H49:AL49) -> 8000000 | H49: 3000000 | I49: 2000000 | J49: 2500000 | K49: 500000
C50: Revenue from Others | D50: EUR | E50: =SUM(H50:AL50) -> 1.043071e+08 | H50: =H45 -> 0 | I50: =I45 -> 0 | J50: =J45 -> 163550.88 | K50: =K45 -> 109898.7 | L50: =L45 -> 162538.01 | M50: =M45 -> 366908.13 | N50: =N45 -> 872190.27 | O50: =O45 -> 754272.96 | ... AL50: =AL45 -> 5649274.5
C51: ARR Revenue (cash) | D51: EUR | E51: =SUM(E49:E50) -> 1.123071e+08 | H51: =SUM(H49:H50) -> 3000000 | I51: =SUM(I49:I50) -> 2000000 | J51: =SUM(J49:J50) -> 2663550.9 | K51: =SUM(K49:K50) -> 609898.7 | L51: =SUM(L49:L50) -> 162538.01 | M51: =SUM(M49:M50) -> 366908.13 | N51: =SUM(N49:N50) -> 872190.27 | O51: =SUM(O49:O50) -> 754272.96 | ... AL51: =SUM(AL49:AL50) -> 5649274.5
D54: Assuming: | F54: Total
...

Sheet 4.2 Revenue Build - Other
B2: ='1. Project Summary'!B2 -> Projections - Serious Shea
B3: ='1. Project Summary'!B3 -> (in EUR, unless otherwise stated)
B5: Revenue Build | D5: Unit | H5: ='2. NPV'!H5 -> 2024 | I5: ='2. NPV'!I5 -> 2025 | J5: ='2. NPV'!J5 -> 2026 | K5: ='2. NPV'!K5 -> 2027 | L5: ='2. NPV'!L5 -> 2028 | M5: ='2. NPV'!M5 -> 2029 | N5: ='2. NPV'!N5 -> 2030 | O5: ='2. NPV'!O5 -> 2031 | ... AL5: ='2. NPV'!AL5 -> 2054
H6: =Period_Start -> 1 | I6: =H6+1 -> 2 | J6: =I6+1 -> 3 | K6: =J6+1 -> 4 | L6: =K6+1 -> 5 | M6: =L6+1 -> 6 | N6: =M6+1 -> 7 | O6: =N6+1 -> 8 | P6: =O6+1 -> 9 | ... AL6: =AK6+1 -> 31
C7: Year count | H7: 1 | I7: =+H7+1 -> 2 | J7: =+I7+1 -> 3 | K7: =+J7+1 -> 4 | L7: =+K7+1 -> 5 | M7: =+L7+1 -> 6 | N7: =+M7+1 -> 7 | O7: =+N7+1 -> 8 | P7: =+O7+1 -> 9 | ... AL7: =+AK7+1 -> 31
B9: Prices
B10: 1 | C10: ='3. Assumptions'!C8 -> Refined Oil | D10: ='3. Assumptions'!D8 -> EUR per metric ton | E10: ='3. Assumptions'!E8 -> 30000 | F10: =IF('1. Project Summary'!$F$13="Real",0,'3. Assumptions'!F8) -> 0.025
B11: ='3. Assumptions'!B9 -> 2 | C11: ='3. Assumptions'!C9 -> Moringa Leaves | D11: ='3. Assumptions'!D9 -> EUR per metric ton | E11: ='3. Assumptions'!E9 -> 5000 | F11: =IF('1. Project Summary'!$F$13="Real",0,'3. Assumptions'!F9) -> 0.025
B12: ='3. Assumptions'!B10 -> 3 | C12: ='3. Assumptions'!C10 -> Dry Mangos | D12: ='3. Assumptions'!D10 -> EUR per metric ton | E12: ='3. Assumptions'!E10 -> 3500 | F12: =IF('1. Project Summary'!$F$13="Real",0,'3. Assumptions'!F10) -> 0.025
B13: ='3. Assumptions'!B11 -> 4 | C13: ='3. Assumptions'!C11 -> Shea Butter | D13: ='3. Assumptions'!D11 -> EUR per metric ton | E13: ='3. Assumptions'!E11 -> 2000 | F13: =IF('1. Project Summary'!$F$13="Real",0,'3. Assumptions'!F11) -> 0.025
B14: ='3. Assumptions'!B12 -> 5 | C14: ='3. Assumptions'!C12 -> Fertilisers Compost | D14: ='3. Assumptions'!D12 -> EUR per metric ton | E14: ='3. Assumptions'!E12 -> 100 | F14: =IF('1. Project Summary'!$F$13="Real",0,'3. Assumptions'!F12) -> 0.025
B15: ='3. Assumptions'!B13 -> 6 | C15: ='3. Assumptions'!C13 -> Biochar | D15: ='3. Assumptions'!D13 -> EUR per metric ton | E15: ='3. Assumptions'!E13 -> 0 | F15: =IF('1. Project Summary'!$F$13="Real",0,'3. Assumptions'!F13) -> 0
B17: Volume | F17: Average
B18: =B10 -> 1 | C18: =C10 -> Refined Oil | D18: tn | F18: =AVERAGE(J18:AL18) -> 461.11034 | H18: ='3. Assumptions'!F166/1000 -> 0 | I18: ='3. Assumptions'!G166/1000 -> 0 | J18: ='3. Assumptions'!H166/1000 -> 161.5 | K18: ='3. Assumptions'!I166/1000 -> 290.7 | L18: ='3. Assumptions'!J166/1000 -> 323 | M18: ='3. Assumptions'!K166/1000 -> 484.5 | N18: ='3. Assumptions'!L166/1000 -> 484.5 | O18: ='3. Assumptions'!M166/1000 -> 484.5 | ... Q18: ='3. Assumptions'!O166/1000 -> 484.5 | R18: =Q18 -> 484.5 | S18: =R18 -> 484.5 | T18: =S18 -> 484.5 | U18: =T18 -> 484.5 | V18: =U18 -> 484.5 | W18: =V18 -> 484.5 | X18: =W18 -> 484.5 | Y18: =X18 -> 484.5 | ... AL18: =AK18 -> 484.5
B19: =B11 -> 2 | C19: =C11 -> Moringa Leaves | D19: tn | F19: =AVERAGE(I19:AL19) -> 94.316 | H19: ='3. Assumptions'!F167/1000 -> 0 | I19: ='3. Assumptions'!G167/1000 -> 58.14 | J19: ='3. Assumptions'!H167/1000 -> 58.14 | K19: ='3. Assumptions'!I167/1000 -> 96.9 | L19: ='3. Assumptions'!J167/1000 -> 96.9 | M19: ='3. Assumptions'!K167/1000 -> 96.9 | N19: ='3. Assumptions'!L167/1000 -> 96.9 | O19: ='3. Assumptions'!M167/1000 -> 96.9 | ... Q19: ='3. Assumptions'!O167/1000 -> 96.9 | R19: =Q19 -> 96.9 | S19: =R19 -> 96.9 | T19: =S19 -> 96.9 | U19: =T19 -> 96.9 | V19: =U19 -> 96.9 | W19: =V19 -> 96.9 | X19: =W19 -> 96.9 | Y19: =X19 -> 96.9 | ... AL19: =AK19 -> 96.9
B20: =B12 -> 3 | C20: =C12 -> Dry Mangos | D20: tn | F20: =AVERAGE(I20:AL20) -> 1349.4 | H20: ='3. Assumptions'!F168/1000 -> 0 | I20: ='3. Assumptions'!G168/1000 -> 173 | J20: ='3. Assumptions'!H168/1000 -> 346 | K20: ='3. Assumptions'!I168/1000 -> 519 | L20: ='3. Assumptions'!J168/1000 -> 692 | M20: ='3. Assumptions'!K168/1000 -> 865 | N20: ='3. Assumptions'!L168/1000 -> 1038 | O20: ='3. Assumptions'!M168/1000 -> 1211 | ... Q20: ='3. Assumptions'!O168/1000 -> 1557 | R20: =Q20 -> 1557 | S20: =R20 -> 1557 | T20: =S20 -> 1557 | U20: =T20 -> 1557 | V20: =U20 -> 1557 | W20: =V20 -> 1557 | X20: =W20 -> 1557 | Y20: =X20 -> 1557 | ... AL20: =AK20 -> 1557
B21: =B13 -> 4 | C21: =C13 -> Shea Butter | D21: tn | F21: =AVERAGE(J21:AL21) -> 0 | H21: ='3. Assumptions'!F169/1000 -> 0 | I21: ='3. Assumptions'!G169/1000 -> 0 | J21: ='3. Assumptions'!H169/1000 -> 0 | K21: ='3. Assumptions'!I169/1000 -> 0 | L21: ='3. Assumptions'!J169/1000 -> 0 | M21: ='3. Assumptions'!K169/1000 -> 0 | N21: ='3. Assumptions'!L169/1000 -> 0 | O21: ='3. Assumptions'!M169/1000 -> 0 | ... Q21: ='3. Assumptions'!O169/1000 -> 0 | R21: =Q21 -> 0 | S21: =R21 -> 0 | T21: =S21 -> 0 | U21: =T21 -> 0 | V21: =U21 -> 0 | W21: =V21 -> 0 | X21: =W21 -> 0 | Y21: =X21 -> 0 | ... AL21: =AK21 -> 0
B22: =B14 -> 5 | C22: =C14 -> Fertilisers Compost | D22: tn | F22: =AVERAGE(I22:AL22) -> 9360 | H22: ='3. Assumptions'!F170/1000 -> 0 | I22: ='3. Assumptions'!G170/1000 -> 1200 | J22: ='3. Assumptions'!H170/1000 -> 2400 | K22: ='3. Assumptions'!I170/1000 -> 3600 | L22: ='3. Assumptions'!J170/1000 -> 4800 | M22: ='3. Assumptions'!K170/1000 -> 6000 | N22: ='3. Assumptions'!L170/1000 -> 7200 | O22: ='3. Assumptions'!M170/1000 -> 8400 | ... Q22: ='3. Assumptions'!O170/1000 -> 10800 | R22: =Q22 -> 10800 | S22: =R22 -> 10800 | T22: =S22 -> 10800 | U22: =T22 -> 10800 | V22: =U22 -> 10800 | W22: =V22 -> 10800 | X22: =W22 -> 10800 | Y22: =X22 -> 10800 | ... AL22: =AK22 -> 10800
B23: =B15 -> 6 | C23: =C15 -> Biochar | D23: tn | F23: =AVERAGE(J23:AL23) -> 0 | H23: ='3. Assumptions'!F171/1000 -> 0 | I23: ='3. Assumptions'!G171/1000 -> 0 | J23: ='3. Assumptions'!H171/1000 -> 0 | K23: ='3. Assumptions'!I171/1000 -> 0 | L23: ='3. Assumptions'!J171/1000 -> 0 | M23: ='3. Assumptions'!K171/1000 -> 0 | N23: ='3. Assumptions'!L171/1000 -> 0 | O23: ='3. Assumptions'!M171/1000 -> 0 | ... Q23: ='3. Assumptions'!O171/1000 -> 0 | R23: =Q23 -> 0 | S23: =R23 -> 0 | T23: =S23 -> 0 | U23: =T23 -> 0 | V23: =U23 -> 0 | W23: =V23 -> 0 | X23: =W23 -> 0 | Y23: =X23 -> 0 | ... AL23: =AK23 -> 0
B25: Revenue
B26: Revenue from products
B27: =B18 -> 1 | C27: =C18 -> Refined Oil | D27: EUR | E27: ='3. Assumptions'!G8 -> 1 | H27: =H18*$E10*(1+$F10)^H$6*$E27 -> 0 | I27: =I18*$E10*(1+$F10)^I$6*$E27 -> 0 | J27: =J18*$E10*(1+$F10)^J$6*$E27 -> 5217535.1 | K27: =K18*$E10*(1+$F10)^K$6*$E27 -> 9626352.2 | L27: =L18*$E10*(1+$F10)^L$6*$E27 -> 10963346 | M27: =M18*$E10*(1+$F10)^M$6*$E27 -> 16856144 | N27: =N18*$E10*(1+$F10)^N$6*$E27 -> 17277547 | O27: =O18*$E10*(1+$F10)^O$6*$E27 -> 17709486 | ... AL27: =AL18*$E10*(1+$F10)^AL$6*$E27 -> 31250348
B28: =B19 -> 2 | C28: =C19 -> Moringa Leaves | D28: EUR | E28: ='3. Assumptions'!G9 -> 1 | H28: =H19*$E11*(1+$F11)^H$6*$E28 -> 0 | I28: =I19*$E11*(1+$F11)^I$6*$E28 -> 305416.69 | J28: =J19*$E11*(1+$F11)^J$6*$E28 -> 313052.1 | K28: =K19*$E11*(1+$F11)^K$6*$E28 -> 534797.35 | L28: =L19*$E11*(1+$F11)^L$6*$E28 -> 548167.28 | M28: =M19*$E11*(1+$F11)^M$6*$E28 -> 561871.46 | N28: =N19*$E11*(1+$F11)^N$6*$E28 -> 575918.25 | O28: =O19*$E11*(1+$F11)^O$6*$E28 -> 590316.2 | ... AL28: =AL19*$E11*(1+$F11)^AL$6*$E28 -> 1041678.3
B29: =B20 -> 3 | C29: =C20 -> Dry Mangos | D29: EUR | E29: ='3. Assumptions'!G10 -> 0.3 | H29: =H20*$E12*(1+$F12)^H$6*$E29 -> 0 | I29: =I20*$E12*(1+$F12)^I$6*$E29 -> 190846.03 | J29: =J20*$E12*(1+$F12)^J$6*$E29 -> 391234.36 | K29: =K20*$E12*(1+$F12)^K$6*$E29 -> 601522.83 | L29: =L20*$E12*(1+$F12)^L$6*$E29 -> 822081.21 | M29: =M20*$E12*(1+$F12)^M$6*$E29 -> 1053291.5 | N29: =N20*$E12*(1+$F12)^N$6*$E29 -> 1295548.6 | O29: =O20*$E12*(1+$F12)^O$6*$E29 -> 1549260.2 | ... AL29: =AL20*$E12*(1+$F12)^AL$6*$E29 -> 3514938.6
B30: =B21 -> 4 | C30: =C21 -> Shea Butter | D30: EUR | E30: ='3. Assumptions'!G11 -> 0.3 | H30: =H21*$E13*(1+$F13)^H$6*$E30 -> 0 | I30: =I21*$E13*(1+$F13)^I$6*$E30 -> 0 | J30: =J21*$E13*(1+$F13)^J$6*$E30 -> 0 | K30: =K21*$E13*(1+$F13)^K$6*$E30 -> 0 | L30: =L21*$E13*(1+$F13)^L$6*$E30 -> 0 | M30: =M21*$E13*(1+$F13)^M$6*$E30 -> 0 | N30: =N21*$E13*(1+$F13)^N$6*$E30 -> 0 | O30: =O21*$E13*(1+$F13)^O$6*$E30 -> 0 | ... AL30: =AL21*$E13*(1+$F13)^AL$6*$E30 -> 0
B31: =B22 -> 5 | C31: =C22 -> Fertilisers Compost | D31: EUR | E31: ='3. Assumptions'!G12 -> 1 | H31: =H22*$E14*(1+$F14)^H$6*$E31 -> 0 | I31: =I22*$E14*(1+$F14)^I$6*$E31 -> 126075 | J31: =J22*$E14*(1+$F14)^J$6*$E31 -> 258453.75 | K31: =K22*$E14*(1+$F14)^K$6*$E31 -> 397372.64 | L31: =L22*$E14*(1+$F14)^L$6*$E31 -> 543075.94 | M31: =M22*$E14*(1+$F14)^M$6*$E31 -> 695816.05 | N31: =N22*$E14*(1+$F14)^N$6*$E31 -> 855853.74 | O31: =O22*$E14*(1+$F14)^O$6*$E31 -> 1023458.4 | ... AL31: =AL22*$E14*(1+$F14)^AL$6*$E31 -> 2322007.3
B32: =B23 -> 6 | C32: =C23 -> Biochar | D32: EUR | E32: ='3. Assumptions'!G13 -> 0 | H32: =H23*$E15*(1+$F15)^H$6*$E32 -> 0 | I32: =I23*$E15*(1+$F15)^I$6*$E32 -> 0 | J32: =J23*$E15*(1+$F15)^J$6*$E32 -> 0 | K32: =K23*$E15*(1+$F15)^K$6*$E32 -> 0 | L32: =L23*$E15*(1+$F15)^L$6*$E32 -> 0 | M32: =M23*$E15*(1+$F15)^M$6*$E32 -> 0 | N32: =N23*$E15*(1+$F15)^N$6*$E32 -> 0 | O32: =O23*$E15*(1+$F15)^O$6*$E32 -> 0 | ... AL32: =AL23*$E15*(1+$F15)^AL$6*$E32 -> 0
B33: ="Total "&B26 -> Total Revenue from products | H33: =SUM(H27:H32) -> 0 | I33: =SUM(I27:I32) -> 622337.72 | J33: =SUM(J27:J32) -> 6180275.3 | K33: =SUM(K27:K32) -> 11160045 | L33: =SUM(L27:L32) -> 12876670 | M33: =SUM(M27:M32) -> 19167123 | N33: =SUM(N27:N32) -> 20004868 | O33: =SUM(O27:O32) -> 20872521 | ... AL33: =SUM(AL27:AL32) -> 38128973
B35: Revenue from processing fee
B36: =B29 -> 3 | C36: =C29 -> Dry Mangos | D36: EUR | E36: ='3. Assumptions'!E16 -> 100 | F36: =IF('1. Project Summary'!$F$13="Real",0,'3. Assumptions'!F16) -> 0.025 | H36: =H20*$E36*(1+$F36)^H$6 -> 0 | I36: =I20*$E36*(1+$F36)^I$6 -> 18175.812 | J36: =J20*$E36*(1+$F36)^J$6 -> 37260.416 | K36: =K20*$E36*(1+$F36)^K$6 -> 57287.889 | L36: =L20*$E36*(1+$F36)^L$6 -> 78293.448 | M36: =M20*$E36*(1+$F36)^M$6 -> 100313.48 | N36: =N20*$E36*(1+$F36)^N$6 -> 123385.58 | O36: =O20*$E36*(1+$F36)^O$6 -> 147548.59 | ... AL36: =AL20*$E36*(1+$F36)^AL$6 -> 334756.05
B37: =B30 -> 4 | C37: =C30 -> Shea Butter | D37: EUR | E37: ='3. Assumptions'!E17 -> 200 | F37: =IF('1. Project Summary'!$F$13="Real",0,'3. Assumptions'!F17) -> 0.025 | H37: =H21*$E37*(1+$F37)^H$6 -> 0 | I37: =I21*$E37*(1+$F37)^I$6 -> 0 | J37: =J21*$E37*(1+$F37)^J$6 -> 0 | K37: =K21*$E37*(1+$F37)^K$6 -> 0 | L37: =L21*$E37*(1+$F37)^L$6 -> 0 | M37: =M21*$E37*(1+$F37)^M$6 -> 0 | N37: =N21*$E37*(1+$F37)^N$6 -> 0 | O37: =O21*$E37*(1+$F37)^O$6 -> 0 | ... AL37: =AL21*$E37*(1+$F37)^AL$6 -> 0
B38: ="Total "&B35 -> Total Revenue from processing fee | H38: =SUM(H36:H37) -> 0 | I38: =SUM(I36:I37) -> 18175.812 | J38: =SUM(J36:J37) -> 37260.416 | K38: =SUM(K36:K37) -> 57287.889 | L38: =SUM(L36:L37) -> 78293.448 | M38: =SUM(M36:M37) -> 100313.48 | N38: =SUM(N36:N37) -> 123385.58 | O38: =SUM(O36:O37) -> 147548.59 | ... AL38: =SUM(AL36:AL37) -> 334756.05
B40: ="Total "&B25 -> Total Revenue | H40: =H33+H38 -> 0 | I40: =I33+I38 -> 640513.53 | J40: =J33+J38 -> 6217535.7 | K40: =K33+K38 -> 11217333 | L40: =L33+L38 -> 12954963 | M40: =M33+M38 -> 19267436 | N40: =N33+N38 -> 20128254 | O40: =O33+O38 -> 21020070 | ... AL40: =AL33+AL38 -> 38463729
B43: Combined Revenue of Serious Shea & its Partners
B44: =B27 -> 1 | C44: =C27 -> Refined Oil | D44: EUR | H44: =H27/$E27*100% -> 0 | I44: =I27/$E27*100% -> 0 | J44: =J27/$E27*100% -> 5217535.1 | K44: =K27/$E27*100% -> 9626352.2 | L44: =L27/$E27*100% -> 10963346 | M44: =M27/$E27*100% -> 16856144 | N44: =N27/$E27*100% -> 17277547 | O44: =O27/$E27*100% -> 17709486 | ... AL44: =AL27/$E27*100% -> 31250348
B45: =B28 -> 2 | C45: =C28 -> Moringa Leaves | D45: EUR | H45: =H28/$E28*100% -> 0 | I45: =I28/$E28*100% -> 305416.69 | J45: =J28/$E28*100% -> 313052.1 | K45: =K28/$E28*100% -> 534797.35 | L45: =L28/$E28*100% -> 548167.28 | M45: =M28/$E28*100% -> 561871.46 | N45: =N28/$E28*100% -> 575918.25 | O45: =O28/$E28*100% -> 590316.2 | ... AL45: =AL28/$E28*100% -> 1041678.3
B46: =B29 -> 3 | C46: =C29 -> Dry Mangos | D46: EUR | H46: =H29/$E29*100% -> 0 | I46: =I29/$E29*100% -> 636153.44 | J46: =J29/$E29*100% -> 1304114.5 | K46: =K29/$E29*100% -> 2005076.1 | L46: =L29/$E29*100% -> 2740270.7 | M46: =M29/$E29*100% -> 3510971.8 | N46: =N29/$E29*100% -> 4318495.3 | O46: =O29/$E29*100% -> 5164200.7 | ... AL46: =AL29/$E29*100% -> 11716462
B47: =B30 -> 4 | C47: =C30 -> Shea Butter | D47: EUR | H47: =H30/$E30*100% -> 0 | I47: =I30/$E30*100% -> 0 | J47: =J30/$E30*100% -> 0 | K47: =K30/$E30*100% -> 0 | L47: =L30/$E30*100% -> 0 | M47: =M30/$E30*100% -> 0 | N47: =N30/$E30*100% -> 0 | O47: =O30/$E30*100% -> 0 | ... AL47: =AL30/$E30*100% -> 0
B48: =B31 -> 5 | C48: =C31 -> Fertilisers Compost | D48: EUR | H48: =H31/$E31*100% -> 0 | I48: =I31/$E31*100% -> 126075 | J48: =J31/$E31*100% -> 258453.75 | K48: =K31/$E31*100% -> 397372.64 | L48: =L31/$E31*100% -> 543075.94 | M48: =M31/$E31*100% -> 695816.05 | N48: =N31/$E31*100% -> 855853.74 | O48: =O31/$E31*100% -> 1023458.4 | ... AL48: =AL31/$E31*100% -> 2322007.3
B49: =B32 -> 6 | C49: =C32 -> Biochar | D49: EUR | H49: =IFERROR(H32/$E32*100%,"") | I49: =IFERROR(I32/$E32*100%,"") | J49: =IFERROR(J32/$E32*100%,"") | K49: =IFERROR(K32/$E32*100%,"") | L49: =IFERROR(L32/$E32*100%,"") | M49: =IFERROR(M32/$E32*100%,"") | N49: =IFERROR(N32/$E32*100%,"") | O49: =IFERROR(O32/$E32*100%,"") | ... AL49: =IFERROR(AL32/$E32*100%,"")
...

Sheet 5.1 Project Dev't & Monitoring
B2: ='1. Project Summary'!B2 -> Projections - Serious Shea
B3: ='1. Project Summary'!B3 -> (in EUR, unless otherwise stated)
B5: Cost Build | D5: Unit | H5: ='2. NPV'!H5 -> 2024 | I5: ='2. NPV'!I5 -> 2025 | J5: ='2. NPV'!J5 -> 2026 | K5: ='2. NPV'!K5 -> 2027 | L5: ='2. NPV'!L5 -> 2028 | M5: ='2. NPV'!M5 -> 2029 | N5: ='2. NPV'!N5 -> 2030 | O5: ='2. NPV'!O5 -> 2031 | ... AL5: ='2. NPV'!AL5 -> 2054
B6: Project Development & Monitoring Costs | H6: ='4.1 Revenue Build - VCU'!H6 -> 1 | I6: ='4.1 Revenue Build - VCU'!I6 -> 2 | J6: ='4.1 Revenue Build - VCU'!J6 -> 3 | K6: ='4.1 Revenue Build - VCU'!K6 -> 4 | L6: ='4.1 Revenue Build - VCU'!L6 -> 5 | M6: ='4.1 Revenue Build - VCU'!M6 -> 6 | N6: ='4.1 Revenue Build - VCU'!N6 -> 7 | O6: ='4.1 Revenue Build - VCU'!O6 -> 8 | ... AL6: ='4.1 Revenue Build - VCU'!AL6 -> 31
B8: Cost Inflation | E8: ='1. Project Summary'!F15 -> 0.02 | H8: =(1+$E$8)^H6 -> 1.02 | I8: =(1+$E$8)^I6 -> 1.0404 | J8: =(1+$E$8)^J6 -> 1.061208 | K8: =(1+$E$8)^K6 -> 1.0824322 | L8: =(1+$E$8)^L6 -> 1.1040808 | M8: =(1+$E$8)^M6 -> 1.1261624 | N8: =(1+$E$8)^N6 -> 1.1486857 | O8: =(1+$E$8)^O6 -> 1.1716594 | ... AL8: =(1+$E$8)^AL6 -> 1.8475888
B10: Project Development Cost
B11: Carbon Technical Work (VCS + CCB)
C12: Feasibility assessment | D12: USD | E12: ='3. Assumptions'!F30 -> 73250 | H12: =E12 -> 73250
C13: Work plan | D13: USD | E13: ='3. Assumptions'!F31 -> 5000 | H13: =E13 -> 5000
C14: Project Description | D14: USD | E14: ='3. Assumptions'!F32 -> 200000 | H14: =$E14*H$18 -> 100000 | I14: =$E14*I$18 -> 100000
C15: Audit support to issuance | D15: USD | E15: ='3. Assumptions'!F33 -> 62500 | H15: =$E15*H$18 -> 31250 | I15: =$E15*I$18 -> 31250
C16: First MIR | D16: USD | E16: ='3. Assumptions'!F34 -> 100000 | H16: =$E16*H$18 -> 50000 | I16: =$E16*I$18 -> 50000
C17: ='3. Assumptions'!C36 -> Additional costs for CCB | D17: USD | E17: ='3. Assumptions'!F36 -> 100000 | H17: =$E17*H$18 -> 50000 | I17: =$E17*I$18 -> 50000
C18: Payment schedule | D18: % | H18: 0.5 | I18: =100%-H18 -> 0.5
B20: Validation Audit
C21: Validation Audit Fee | D21: USD | E21: ='3. Assumptions'!F35 -> 22500 | H21: =IF('4.1 Revenue Build - VCU'!H$7='5.1 Project Dev''t & Monitoring'!$E$22,$E21,0)*H8 -> 0 | I21: =IF('4.1 Revenue Build - VCU'!I$7='5.1 Project Dev''t & Monitoring'!$E$22,$E21,0)*I8 -> 23409 | J21: =IF('4.1 Revenue Build - VCU'!J$7='5.1 Project Dev''t & Monitoring'!$E$22,$E21,0)*J8 -> 0 | K21: =IF('4.1 Revenue Build - VCU'!K$7='5.1 Project Dev''t & Monitoring'!$E$22,$E21,0)*K8 -> 0 | L21: =IF('4.1 Revenue Build - VCU'!L$7='5.1 Project Dev''t & Monitoring'!$E$22,$E21,0)*L8 -> 0 | M21: =IF('4.1 Revenue Build - VCU'!M$7='5.1 Project Dev''t & Monitoring'!$E$22,$E21,0)*M8 -> 0 | N21: =IF('4.1 Revenue Build - VCU'!N$7='5.1 Project Dev''t & Monitoring'!$E$22,$E21,0)*N8 -> 0 | O21: =IF('4.1 Revenue Build - VCU'!O$7='5.1 Project Dev''t & Monitoring'!$E$22,$E21,0)*O8 -> 0 | ... AL21: =IF('4.1 Revenue Build - VCU'!AL$7='5.1 Project Dev''t & Monitoring'!$E$22,$E21,0)*AL8 -> 0
C22: Year of validation | D22: Year | E22: ='3. Assumptions'!F24 -> 2
B23: ="Total "&B10 -> Total Project Development Cost | D23: USD | E23: =SUM(H23:AL23) -> 564159 | H23: =SUM(H12:H17,H21:H22) -> 309500 | I23: =SUM(I12:I17,I21:I22) -> 254659 | J23: =SUM(J13:J16,J21:J22) -> 0 | K23: =SUM(K13:K16,K21:K22) -> 0 | L23: =SUM(L13:L16,L21:L22) -> 0 | M23: =SUM(M13:M16,M21:M22) -> 0 | N23: =SUM(N13:N16,N21:N22) -> 0 | O23: =SUM(O13:O16,O21:O22) -> 0 | P23: =SUM(P13:P16,P21:P22) -> 0 | Q23: =SUM(Q13:Q16,Q21:Q22) -> 0 | ... AL23: =SUM(AL13:AL16,AL21:AL22) -> 0
B24: =B23 -> Total Project Development Cost | D24: EUR | E24: =SUM(H24:AL24) -> 512173.4 | H24: =H23/'1. Project Summary'!$F$16 -> 280980.48 | I24: =I23/'1. Project Summary'!$F$16 -> 231192.92 | J24: =J23/'1. Project Summary'!$F$16 -> 0 | K24: =K23/'1. Project Summary'!$F$16 -> 0 | L24: =L23/'1. Project Summary'!$F$16 -> 0 | M24: =M23/'1. Project Summary'!$F$16 -> 0 | N24: =N23/'1. Project Summary'!$F$16 -> 0 | O24: =O23/'1. Project Summary'!$F$16 -> 0 | ... AL24: =AL23/'1. Project Summary'!$F$16 -> 0
B26: Project Monitoring Cost
B28: Registration Fees and Issuance Levies (VCS + CCB)
C29: Total VCU Issuance | D29: VCUs | E29: =SUM(H29:AL29) -> 8089676 | H29: ='4.1 Revenue Build - VCU'!H39 -> 0 | I29: ='4.1 Revenue Build - VCU'!I39 -> 0 | J29: ='4.1 Revenue Build - VCU'!J39 -> 45720 | K29: ='4.1 Revenue Build - VCU'!K39 -> 85356 | L29: ='4.1 Revenue Build - VCU'!L39 -> 127016 | M29: ='4.1 Revenue Build - VCU'!M39 -> 173232 | N29: ='4.1 Revenue Build - VCU'!N39 -> 219448 | O29: ='4.1 Revenue Build - VCU'!O39 -> 265664 | ... AL29: ='4.1 Revenue Build - VCU'!AL39 -> 311880
B31: 1 | C31: Verra Registry Account Opening Fee VCS | D31: USD | E31: ='3. Assumptions'!F39 -> 500 | H31: =$E31*H$8 -> 510
B33: 2 | C33: VCS Account Maintenance Fee | D33: ='3. Assumptions'!D40 -> USD per annum | E33: ='3. Assumptions'!F39 -> 500 | H33: =$E33*H$8 -> 510 | I33: =$E33*I$8 -> 520.2 | J33: =$E33*J$8 -> 530.604 | K33: =$E33*K$8 -> 541.21608 | L33: =$E33*L$8 -> 552.0404 | M33: =$E33*M$8 -> 563.08121 | N33: =$E33*N$8 -> 574.34283 | O33: =$E33*O$8 -> 585.82969 | ... AL33: =$E33*AL$8 -> 923.79441
B35: 3 | C35: VCS Pipeline Listing request fee | D35: ='3. Assumptions'!D41 -> USD | E35: ='3. Assumptions'!F41 -> 1000 | H35: =$E35*H$8 -> 1020
B37: 4 | C37: Project registeration request review fee | D37: ='3. Assumptions'!D42 -> USD | E37: ='3. Assumptions'!F42 -> 2500 | H37: =$E37*H$8 -> 2550
B39: 5 | C39: VCS Issuance Levy | D39: ='3. Assumptions'!D43 -> USD per VCU | E39: ='3. Assumptions'!F43 -> 0.2 | H39: =H29*$E39*H$8 -> 0 | I39: =I29*$E39*I$8 -> 0 | J39: =J29*$E39*J$8 -> 9703.686 | K39: =K29*$E39*K$8 -> 18478.416 | L39: =L29*$E39*L$8 -> 28047.185 | M39: =M29*$E39*M$8 -> 39017.474 | N39: =N29*$E39*N$8 -> 50415.354 | O39: =O29*$E39*O$8 -> 62253.544 | ... AL39: =AL29*$E39*AL$8 -> 115245.2
B41: 6 | C41: CCB Label Fee | D41: ='3. Assumptions'!D44 -> USD per label | E41: ='3. Assumptions'!F44 -> 0.07 | H41: =H29*$E41*H$8 -> 0 | I41: =I29*$E41*I$8 -> 0 | J41: =J29*$E41*J$8 -> 3396.2901 | K41: =K29*$E41*K$8 -> 6467.4456 | L41: =L29*$E41*L$8 -> 9816.5149 | M41: =M29*$E41*M$8 -> 13656.116 | N41: =N29*$E41*N$8 -> 17645.374 | O41: =O29*$E41*O$8 -> 21788.74 | ... AL41: =AL29*$E41*AL$8 -> 40335.82
B43: 7 | C43: VCS Verification
