Workbook

Sheet Cover
A1: Business Case Agroforestry Project
A2: Name Local Partner (LP) | B2: Golden Organics
A3: Date | B3: 45075
A4: Currency | B4: EUR
A5: Conversion to EUR | B5: 1
A7: In case of questions related to the functioning or use of this template, please reach out to
A8: Max Berkelmans
A9: max.berkelmans@rabobank.com
A11: Margreet Muizebelt
A12: margreet.muizebelt@rabobank.com

Sheet Overview
A1: Overview Business Case
A2: Introduction
A3: This Business Case provides the LP and Acorn with an overview of the income and costs associated with the implementation and ongoing management of an agrofrestry project. This template aims to cover various agroforestry designs, but therefore makes certain assumptions which may not apply to all individual projects. The following assumptions are made: 1. A farmer has a maximum of 5 main crops 2. A maximum of 5 different tree species are planted as part of the intervention 3. Trees are planted during a maximum time period of three subsequent years 4. The implementation period (when farmers are added to the project and trees are planted) is a maximum of 7 years. In case these assumptions do not apply to your specific project or you would like to add some additional information, please reach out to Acorn.
A10: Legend
A11: Please consider the following when filling out the business case
B12: Cel | D12: Explanation
B13: Acorn assumption | D13: Hard coded input (these cells are locked and cannot be changed)
B14: Input Local Partner | D14: Input based on agroforestry project (please provide your input here)
B15: Calculation | D15: Calculated output (these cells are locked and cannot be changed)
A17: Structure
B18: Sheet | D18: Description
B20: Input - Assumptions | D20: Overview of the key assumptions of the business case and agroforestry design. These assumptions are fixed and apply during the entire project period.
B23: Input -Assumptions per year | D23: Overview of the key assumptions that differ per year.
B26: Input - Budget Farmer | D26: Overview of the budget/transition costs on farmer level to implement agroforestry practices
B29: Input - Budget Local Partner | D29: Overview for the Local Partner of all of the activities and costs related to the Acorn program
B32: Output - Farmer | D32: Overview of the costs and benefits of the Agroforestry project on Farmer level
B35: Output - Local Partner Level | D35: Overview of the costs and benefits of the Agroforestry project on the Local Partner level
B38: Output - Project level | D38: Overview of te cost and benefits of the Agroforestry project on a Project Level

Sheet Summary
A1: Summary
A2: Agroforestry Impact - Farmer
A3: Item | B3: Unit | C3: Value | D3: Description
A4: Baseline income farmer | B4: EUR/year | C4: ='Output Farmer'!$E$9 -> 0 | D4: The annual income of a farmer in the baseline scenario (i.e. before the agroforestry intervention)
A5: Surviving trees | B5: # | C5: ='Output Farmer'!$I$31 -> 466 | D5: The number of surviving trees resulting from the agroforestry intervention
A6: Farmer package | B6: EUR | C6: =SUM('Output Farmer'!$E$20:$Y$20) -> 972.01239 | D6: The total investment costs to transition to agroforestry (seedling costs, tree planting costs and training)
A7: Additional revenue main crop | B7: EUR/year | C7: =AVERAGE('Output Farmer'!E24:Y24) -> 131.42857 | D7: Additional revenue from main crop due to productivity increases resulting from the agroforestry intervention
A8: Additional revenue from producing trees | B8: EUR/year | C8: =AVERAGE('Output Farmer'!E28:Y28) -> 3551.4286 | D8: Additional revenue from yield producing trees resulting from the agroforestry intervention
A9: Reduced spending on inputs | B9: EUR/year | C9: =AVERAGE('Output Farmer'!E25:Y25) -> -140.95238 | D9: Annual reduced spending on input costs (e.g. fertilizer) due to agroforestry intervention
A10: Average carbon revenue | B10: EUR/year | C10: =AVERAGE('Output Farmer'!$E$39:$Y$39) -> 0 | D10: Average additional carbon revenue in a 20 years period because of Carbon Removal Units (CRUs) generated through Acorn
A11: Total carbon revenue | B11: EUR | C11: =SUM('Output Farmer'!$E$39:$Y$39) -> 0 | D11: Total additional carbon revenue in a 20 years period because of Carbon Removal Units (CRUs) generated through Acorn
A12: Additional carbon revenue on top of baseline | B12: % | C12: =IFERROR(AVERAGE('Output Farmer'!$E$47:$Y$47),"-") -> - | D12: Additional carbon revenue on top of baseline due to agroforestry intervention (average of 20 years period)
A13: Total impact of agroforestry intervention on baseline | B13: % | C13: =IFERROR(AVERAGE('Output Farmer'!$E$46:$Y$46),"-") -> - | D13: Total impact of agroforestry intervention on baseline including all benefits (e.g. productivity increase, yield increase, reduced input costs)
A34: Agroforestry Impact - Local Partner
A35: Item | B35: Unit | C35: Value | D35: Description
A36: Total number of farmers | B36: # | C36: ='Output LP'!$Y$7 -> 27124.774 | D36: The total number of farmers participating in the entire project (6 year period)
A37: Total CRU revenue for Local Partner | B37: EUR | C37: ='Output LP'!$C$11 -> 0 | D37: The total CRU revenue that the LP may retain (10% of CRU revenue)
A38: Total Costs Local Partner | B38: EUR | C38: ='Output LP'!$C$22 -> 47814730 | D38: Total Local Partner Project costs (have to be covered by 10% of CRU revenue)
A39: Funding gap | B39: EUR | C39: =MIN('Output LP'!E26:Y26) -> -47814730 | D39: Funding gap due to timing difference of incoming CRU revenue and local partner project costs (due to ex-post character of CRUs)
A40: How funding gap is addressed | B40: Text | C40: To be filled out by Acorn

Sheet Assumptions
A1: Assumptions
A2: Assumption | B2: Unit | C2: Description | D2: Value | F2: Crop and tree specie types
A3: Agroforestry design | F3: Overview baseline: (main) cash crops
A4: Year | B4: date | C4: The year and month in which the agroforestry project starts (year 0) | D4: 45170 | F4: # | G4: Crop | H4: Yield crop | I4: Market price | J4: Total input costs
A5: Land per farmer | B5: ha | C5: The average size of land of the participating farmers | D5: 1 | G5: Name | H5: kg/ha/yr | I5: =Cover!B4&"/kg" -> EUR/kg | J5: =Cover!B4&"/ha/yr" -> EUR/ha/yr
A6: Number of main crops | B6: # | C6: The number of (main) cash crops that are cultivated in the project | D6: 2 | F6: 1 | G6: Groundnut | H6: 1200 | I6: 0.2 | J6: 200
A7: Number of trees planted | B7: # | C7: The number of additional tree specie types that will be planted | D7: 5 | F7: 2 | G7: Maize | H7: 1600 | I7: 0.15 | J7: 250
A8: Maintenance costs | B8: =Cover!B4&"/ha" -> EUR/ha | C8: The additional labour costs for a participating farmer per year for pruning, harvesting, maintenance etc. | F8: 3 | G8: Sorghum | H8: 1400 | I8: 0.1 | J8: 200
A9: Expected productivity change | B9: % | C9: The expected % change in yield of the main crops due to the agroforestry intervention (first 5 years) | D9: =IFERROR('Assumptions (year)'!B91,0) -> 0.2 | F9: 4 | G9: Millet | H9: 1200 | I9: 0.15 | J9: 150
A10: Land use main crop | B10: % | C10: The percentage of land used for growing the main crop before the agroforestry intervention | D10: 0.9 | F10: 5 | G10: Sorghum
A11: Presence of forests | B11: % | C11: Is the project area surrounded by forest (>60% tree cover, Yes = 1, No = 0) | D11: 0
A12: Farmer compensation | B12: Yes/No | C12: In case farmers experience yield decreases of their main crops in the short term, will they be compensated and how? please describe the reason for (no)compensation and if compensation is in kind or in cash. | D12: TBD
A13: Timber harvesting | B13: Yes/No | C13: Is timber harvesting part of the agroforestry design | D13: No
A14: Timber harvesting | B14: tekst | C14: if yes, how often are trees harvested? E.g. once a year, after 5 years | D14: 1
C15: if yes, what proportion (% of total trees planted) is being harvested? | D15: 2
C16: if yes, are harvested trees being replanted (and how) e.g. replanting scheme? | D16: 3
A18: CRU proceeds | F18: Agroforestry intervention
A19: CRU price | B19: EUR/tCO2 | C19: Price received per Carbon Removal Unit (CRU). Acorn guarantees EUR 20/CRU. | D19: 20 | F19: # | G19: Specie | H19: Trees year 0 | I19: Trees year 1 | J19: Trees year 2 | K19: Seedling costs | L19: Market price | M19: Survival rate | N19: Economic Benefits | O19: Environmental Benefits
A20: CRU proceeds to farmer | B20: % | C20: The minimum percentage of the CRU proceeds that flow to the farmer (excluding interest costs) | D20: 0.8 | G20: Name | H20: #/ha | I20: #/ha | J20: #/ha | K20: =Cover!B4&"/seedling" -> EUR/seedling | L20: =Cover!B4&"/kg" -> EUR/kg | M20: % | N20: description | O20: description
A21: Costs Local Partner | B21: % | C21: The maximum percentage of the CRU proceeds that flow to the LP. | D21: 0.1 | F21: 1 | G21: Acacia Mellifera | H21: 533 | I21: 0 | J21: 0 | K21: 0.6 | L21: 0 | M21: 0.8
A22: Costs Acorn | B22: % | C22: The maximum percentage withhold by Acorn to cover costs for monitoring, registering and verification. | D22: 0.1 | F22: 2 | G22: Acacia Senegalensis | H22: 10 | I22: 0 | J22: 0 | K22: 0.6 | L22: 1.25 | M22: 0.8
A23: CRU adjustment - buffer pool | B23: % | C23: The percentage of biomass growth that has to be reserved in a buffer pool for potential reversal events | D23: 0.15 | F23: 3 | G23: Baobab | H23: 10 | I23: 0 | J23: 0 | K23: 0.6 | L23: 8 | M23: 0.8
A24: CRU adjustment - leakage | B24: % | C24: The loss of biomass in non-project areas caused by shifting land use activities in the project area | D24: =IF(D9>0,1,1-D11*D10*(-D9)) -> 1 | F24: 4 | G24: Balanites | H24: 20 | I24: 0 | J24: 0 | K24: 0.6 | L24: 1 | M24: 0.8
F25: 5 | G25: Tallow | H25: 10 | I25: 0 | J25: 0 | K25: 0.6 | L25: 1 | M25: 0.8

Sheet Assumptions (year)
A1: Assumptions per year
A2: Program year | E2: 0 | F2: =E2+1 -> 1 | G2: =F2+1 -> 2 | H2: =G2+1 -> 3 | I2: =H2+1 -> 4 | J2: =I2+1 -> 5 | K2: =J2+1 -> 6 | L2: =K2+1 -> 7 | M2: =L2+1 -> 8 | ... Y2: =X2+1 -> 20
A3: Year | E3: =Assumptions!$D$4 -> 45170 | F3: =EDATE(E3,(1*12)) -> 45536 | G3: =EDATE(F3,(1*12)) -> 45901 | H3: =EDATE(G3,(1*12)) -> 46266 | I3: =EDATE(H3,(1*12)) -> 46631 | J3: =EDATE(I3,(1*12)) -> 46997 | K3: =EDATE(J3,(1*12)) -> 47362 | L3: =EDATE(K3,(1*12)) -> 47727 | M3: =EDATE(L3,(1*12)) -> 48092 | ... Y3: =EDATE(X3,(1*12)) -> 52475
A4: Participants
A5: Number of farmers | B5: # | C5: The number of NEW participating farmers to the project | E5: 1808.3183 | F5: 3616.6365 | G5: 5424.9548 | H5: 5424.9548 | I5: 5424.9548 | J5: 5424.9548
A7: Crops | B7: Unit | C7: Description
A8: =IF(ISBLANK(Assumptions!G6),"",Assumptions!G6) -> Groundnut
A9: Change in productivity | B9: % | C9: The percentage change in yields due to the agroforestry design | E9: -0.05 | F9: 0 | G9: 0.05 | H9: 0.1 | I9: 0.15 | J9: 0.2
A10: Change in input costs | B10: % | C10: The percentage change in input costs (e.g. fertilizer) due to the agroforestry design | E10: 0 | F10: -0.05 | G10: -0.1 | H10: -0.15 | I10: -0.2 | J10: -0.2
A12: =IF(ISBLANK(Assumptions!G7),"",Assumptions!G7) -> Maize
A13: Change in productivity | B13: % | C13: The percentage change in yields due to the agroforestry design | E13: -0.05 | F13: 0 | G13: 0.05 | H13: 0.1 | I13: 0.15 | J13: 0.2
A14: Change in input costs | B14: % | C14: The percentage change in input costs (e.g. fertilizer) due to the agroforestry design | E14: 0 | F14: -0.05 | G14: -0.1 | H14: -0.15 | I14: -0.2 | J14: -0.2
A16: =IF(ISBLANK(Assumptions!G8),"",Assumptions!G8) -> Sorghum
A17: Change in productivity | B17: % | C17: The percentage change in yields due to the agroforestry design | E17: -0.05 | F17: 0 | G17: 0.05 | H17: 0.1 | I17: 0.15 | J17: 0.2
A18: Change in input costs | B18: % | C18: The percentage change in input costs (e.g. fertilizer) due to the agroforestry design | E18: 0 | F18: -0.05 | G18: -0.1 | H18: -0.15 | I18: -0.2 | J18: -0.2
A20: =IF(ISBLANK(Assumptions!G9),"",Assumptions!G9) -> Millet
A21: Change in productivity | B21: % | C21: The percentage change in yields due to the agroforestry design | E21: -0.05 | F21: 0 | G21: 0.05 | H21: 0.1 | I21: 0.15 | J21: 0.2
A22: Change in input costs | B22: % | C22: The percentage change in input costs (e.g. fertilizer) due to the agroforestry design | E22: 0 | F22: -0.05 | G22: -0.1 | H22: -0.15 | I22: -0.2 | J22: -0.2
A24: =IF(ISBLANK(Assumptions!G10),"",Assumptions!G10) -> Sorghum
A25: Change in productivity | B25: % | C25: The percentage change in yields due to the agroforestry design
A26: Change in input costs | B26: % | C26: The percentage change in input costs (e.g. fertilizer) due to the agroforestry design
A28: Trees | B28: Unit | C28: Description
A29: =IF(ISBLANK(Assumptions!G21),"",Assumptions!G21) -> Acacia Mellifera
A30: Average yield per tree | B30: kg/tree | C30: The expected yield (fruits/nuts) per tree | E30: 0 | F30: 0 | G30: 0 | H30: 0 | I30: 0 | J30: 0 | K30: 0 | L30: 0 | M30: 0 | N30: 0 | O30: 0 | P30: 0 | Q30: 0 | R30: 0 | S30: 0 | T30: 0 | U30: 0 | V30: 0 | W30: 0 | X30: 0 | Y30: 0
A31: Annual carbon sequestration | B31: kg CO2/tree | C31: The annual expected carbon sequestration per tree
A32: Number of surviving trees | B32: #/ha | C32: The number of surviving trees | E32: =$B$60 -> 426 | F32: =$C$60+E32 -> 426 | G32: =$D$60+F32 -> 426 | H32: =G32 -> 426 | I32: =H32 -> 426 | J32: =I32 -> 426 | K32: =J32 -> 426 | L32: =K32 -> 426 | M32: =L32 -> 426 | N32: =M32 -> 426 | O32: =N32 -> 426 | ... Y32: =X32 -> 426
A34: =IF(ISBLANK(Assumptions!G22),"",Assumptions!G22) -> Acacia Senegalensis
A35: Average yield per tree | B35: kg/tree | C35: The expected yield (fruits/nuts) per tree | E35: 0 | F35: 0 | G35: 4 | H35: 6 | I35: 8 | J35: 10 | K35: 10 | L35: 10 | M35: 10 | N35: 10 | O35: 10 | P35: 10 | Q35: 10 | R35: 10 | S35: 10 | T35: 10 | U35: 10 | V35: 10 | W35: 10 | X35: 10 | Y35: 10
A36: Annual carbon sequestration | B36: kg CO2/tree | C36: The annual expected carbon sequestration per tree
A37: Number of surviving trees | B37: #/ha | C37: The number of surviving trees | E37: =$B$61 -> 8 | F37: =$C$61+E37 -> 8 | G37: =$D$61+ F37 -> 8 | H37: =G37 -> 8 | I37: =H37 -> 8 | J37: =I37 -> 8 | K37: =J37 -> 8 | L37: =K37 -> 8 | M37: =L37 -> 8 | N37: =M37 -> 8 | O37: =N37 -> 8 | ... Y37: =X37 -> 8
A39: =IF(ISBLANK(Assumptions!G23),"",Assumptions!G23) -> Baobab
A40: Average yield per tree | B40: kg/tree | C40: The expected yield (fruits/nuts) per tree | E40: 0 | F40: 0 | G40: 0 | H40: 0 | I40: 0 | J40: 0 | K40: 5 | L40: 10 | M40: 15 | N40: 25 | O40: 40 | P40: 50 | Q40: 50 | R40: 55 | S40: 60 | T40: 65 | U40: 70 | V40: 80 | W40: 90 | X40: 100 | Y40: 100
A41: Annual carbon sequestration | B41: kg CO2/tree | C41: The annual expected carbon sequestration per tree
A42: Number of surviving trees | B42: #/ha | C42: The number of surviving trees | E42: =$B$62 -> 8 | F42: =$C$62+E42 -> 8 | G42: =$D$62+F42 -> 8 | H42: =G42 -> 8 | I42: =H42 -> 8 | J42: =I42 -> 8 | K42: =J42 -> 8 | L42: =K42 -> 8 | M42: =L42 -> 8 | N42: =M42 -> 8 | O42: =N42 -> 8 | ... Y42: =X42 -> 8
A44: =IF(ISBLANK(Assumptions!G24),"",Assumptions!G24) -> Balanites
A45: Average yield per tree | B45: kg/tree | C45: The expected yield (fruits/nuts) per tree | E45: 0 | F45: 0 | G45: 0 | H45: 0 | I45: 0 | J45: 5 | K45: 10 | L45: 15 | M45: 20 | N45: 25 | O45: 30 | P45: 35 | Q45: 40 | R45: 45 | S45: 50 | T45: 50 | U45: 50 | V45: 50 | W45: 50 | X45: 50 | Y45: 50
A46: Annual carbon sequestration | B46: kg CO2/tree | C46: The annual expected carbon sequestration per tree
A47: Number of surviving trees | B47: #/ha | C47: The number of surviving trees | E47: =$B$63 -> 16 | F47: =$C$63+E47 -> 16 | G47: =$D$63+F47 -> 16 | H47: =G47 -> 16 | I47: =H47 -> 16 | J47: =I47 -> 16 | K47: =J47 -> 16 | L47: =K47 -> 16 | M47: =L47 -> 16 | N47: =M47 -> 16 | O47: =N47 -> 16 | ... Y47: =X47 -> 16
A49: =IF(ISBLANK(Assumptions!G25),"",Assumptions!G25) -> Tallow
A50: Average yield per tree | B50: kg/tree | C50: The expected yield (fruits/nuts) per tree | E50: 0 | F50: 5 | G50: 10 | H50: 15 | I50: 20 | J50: 25 | K50: 30 | L50: 35 | M50: 40 | N50: 50 | O50: 60 | P50: 70 | Q50: 80 | R50: 90 | S50: 100 | T50: 110 | U50: 120 | V50: 130 | W50: 140 | X50: 150 | Y50: 150
...

Sheet Budget Farmer
A1: Budget Farmer
A2: This overview shows the required investments for a farmer to transition to an agroforestry system on its land.
A4: Cost item | B4: Description | D4: Unit
A5: Seedling costs | B5: For reference only | E5: ='Assumptions (year)'!E$3 -> 45170 | F5: ='Assumptions (year)'!F$3 -> 45536 | G5: ='Assumptions (year)'!G$3 -> 45901 | H5: ='Assumptions (year)'!H$3 -> 46266 | I5: ='Assumptions (year)'!I$3 -> 46631 | J5: ='Assumptions (year)'!J$3 -> 46997
A6: Number of seedlings | B6: Number of seedlings per hectare | D6: ha | E6: ='Output Farmer'!E12 -> 583 | F6: ='Output Farmer'!F12 -> 0 | G6: ='Output Farmer'!G12 -> 0 | H6: ='Output Farmer'!H12 -> 0 | I6: ='Output Farmer'!I12 -> 0 | J6: ='Output Farmer'!J12 -> 0
A7: Total seedling costs | B7: Total seedling costs per farmer | D7: =Cover!B4&"/ha" -> EUR/ha | E7: =IFERROR('Output Farmer'!E14/Cover!$B$5,"-") -> 349.8 | F7: =IFERROR('Output Farmer'!F14/Cover!$B$5,"-") -> 0 | G7: =IFERROR('Output Farmer'!G14/Cover!$B$5,"-") -> 0 | H7: =IFERROR('Output Farmer'!H14/Cover!$B$5,"-") -> 0 | I7: =IFERROR('Output Farmer'!I14/Cover!$B$5,"-") -> 0 | J7: =IFERROR('Output Farmer'!J14/Cover!$B$5,"-") -> 0
A9: Cost item | B9: Description | D9: Unit
A10: Tree planting costs (e.g. fertilizer, distribution, ground preparation etc.) Leave blank if not applicable | E10: ='Assumptions (year)'!E$3 -> 45170 | F10: ='Assumptions (year)'!F$3 -> 45536 | G10: ='Assumptions (year)'!G$3 -> 45901 | H10: ='Assumptions (year)'!H$3 -> 46266 | I10: ='Assumptions (year)'!I$3 -> 46631 | J10: ='Assumptions (year)'!J$3 -> 46997
A11: Distribution, transport* | B11: Cost related to the transport and distribution of tree seedlings | D11: =Cover!$B$4&"/ha" -> EUR/ha | E11: =583*0.25 -> 145.75 | F11: =583*0.25 -> 145.75 | G11: =583*0.25 -> 145.75 | H11: =583*0.25 -> 145.75 | I11: =583*0.25 -> 145.75 | J11: =583*0.25 -> 145.75
A12: Ground preparation material and hired labor* | B12: Please describe the method of ground preparation in this cell | D12: =Cover!$B$4&"/ha" -> EUR/ha | E12: 0 | F12: 0 | G12: 0 | H12: 0 | I12: 0 | J12: 0
A13: Fertilizer/manure* | B13: Purchase of fertilizer and/or manure if needed | D13: =Cover!$B$4&"/ha" -> EUR/ha | E13: =583*0.1 -> 58.3 | F13: =583*0.1 -> 58.3 | G13: =583*0.1 -> 58.3 | H13: =583*0.1 -> 58.3 | I13: =583*0.1 -> 58.3 | J13: =583*0.1 -> 58.3
A14: Nursery materials* | B14: If seedlings are grown by the farmer communities | D14: =Cover!$B$4&"/ha" -> EUR/ha | E14: 0 | F14: 0 | G14: 0 | H14: 0 | I14: 0 | J14: 0
A15: Total | E15: =SUM(E11:E14) -> 204.05 | F15: =SUM(F11:F14) -> 204.05 | G15: =SUM(G11:G14) -> 204.05 | H15: =SUM(H11:H14) -> 204.05 | I15: =SUM(I11:I14) -> 204.05 | J15: =SUM(J11:J14) -> 204.05
A17: Cost item | B17: Description | D17: Unit
A18: Training and administration costs | E18: ='Assumptions (year)'!E$3 -> 45170 | F18: ='Assumptions (year)'!F$3 -> 45536 | G18: ='Assumptions (year)'!G$3 -> 45901 | H18: ='Assumptions (year)'!H$3 -> 46266 | I18: ='Assumptions (year)'!I$3 -> 46631 | J18: ='Assumptions (year)'!J$3 -> 46997
A19: Training costs per farmer* | B19: Training of lead farmers on maintenance/harvesting etc. (cost of venue, food, transport per workshop + lead farmer - farmer ratio) | D19: =Cover!$B$4&"/farmer" -> EUR/farmer | E19: =IFERROR((E21/(E20*E22)),"-") -> 3.191875 | F19: =IF($E$23>1,E19*1.05,"-") -> 3.3514687 | G19: =IF($E$23>2,F19*1.05,"-") -> 3.5190422 | H19: =IF($E$23>3,G19*1.05,"-") -> - | I19: =IF($E$23>4,H19*1.05,"-") -> - | J19: =IF($E$23>5,I19*1.05,"-") -> -
B20: > Groups size of lead farmers | D20: Number | E20: 40
B21: > Total cost of venue, food and transport per group | D21: =Cover!$B$4&"/meeting" -> EUR/meeting | E21: 5107
B22: > How many farmers will the Lead Farmers train? | D22: Number | E22: 40
B23: > How many years of training are you providing | D23: years | E23: 3 | F23: An inflation of 5% per year is taken into account
A24: CRU-payout costs* | B24: The costs to make a banktranfer to pay out a CRU to the farmer | D24: =Cover!$B$4&"/farmer" -> EUR/farmer | E24: 1
A26: Total farmer costs | E26: =IFERROR(E7+E15+E19+$E$24,"-") -> 558.04188 | F26: =IFERROR(F7+F15+F19+$E$24,"-") -> 208.40147 | G26: =IFERROR(G7+G15+G19+$E$24,"-") -> 208.56904 | H26: =IFERROR(H7+H15+H19+$E$24,"-") -> - | I26: =IFERROR(I7+I15+I19+$E$24,"-") -> - | J26: =IFERROR(J7+J15+J19+$E$24,"-") -> -
A28: *Please add the underlying calculations and/or explain assumptions below
A29: Distribution of 1.46 Eur per Seedling:
A31: 0.5 Eur per seedling will be paid to the farmers for the production of seedlings in Nurseries
A32: 0.15 Eur per seedling will be paid to the farmers for the supply of inputs
A33: 0.25 eur per seedling will be paid for the transportation to Serious Shea Senegal
A34: 0.25 Eur per seedling will be paid for the planting to the Farmers
A35: 0.35 Eur per Seedling will be paid to the Serious Shea Senegal

Sheet Budget LP
A1: Budget Local Partner
A2: This overview shows the key activities that are directly related to set up an Agroforestry project with Acorn
A5: Assumption | B5: Description | E5: Unit | G5: Value
A6: Key project cost
A7: Cost of agroforestry design | B7: Cost of hiring external agronomist advise on agroforestry design | E7: =Cover!$B$4 -> EUR | G7: 50000
A8: One off project cost | B8: Cost of Acorn documents like Eligibility, Aditionality, Project Summary, ADD | E8: =Cover!$B$4 -> EUR | G8: =92*G9 -> 920
B9: > salary cost per hour (office staff or field technician) | E9: =Cover!$B$4 -> EUR | G9: 10
A10: Farmer engagement cost | B10: Organising meetings to create awareness of agroforesty and Acorn | E10: =Cover!$B$4&"/farmer" -> EUR/farmer | G10: =IFERROR(G12/(G11+G13),0) -> 37.5
B11: > Average number of (Lead)farmers attending these meetings | E11: # | G11: 40
B12: > Total cost of food, transport per meeting | E12: =Cover!$B$4 -> EUR | G12: 3000
B13: > How many farmers will the Lead Farmers inform | E13: # | G13: 40
B14: > cost of communication material (e.g. leaflets, posters, promotion material) per farmer | E14: =Cover!$B$4&"/farmer" -> EUR/farmer | G14: 12
A15: Farmer data collection cost | B15: Enumerator cost for collecting data: e.g. polygon, agreements, land tenure check | E15: =Cover!$B$4&"/farmer" -> EUR/farmer | G15: =IFERROR(G17/G16,0) -> 8.3333333
B16: > How many polygons and survey can one enumerator collect per day | E16: # | G16: 6
B17: > Daily salary/fee paid to enumerator for data collection | E17: =Cover!$B$4&"/day" -> EUR/day | G17: 50
B18: > How many enumerators will be hired | E18: # | G18: 30
B19: > Cost per collection device (GPS phone or tablet) | E19: =Cover!$B$4&"/device" -> EUR/device | G19: 300
A20: Project council cost | B20: Organising and reporting on project council | E20: =Cover!$B$4&"/farmer" -> EUR/farmer | G20: =IFERROR(G22/(G21+G23),0) -> 29.70297
B21: > Average number of representatives of a project council | E21: # | G21: 1
B22: > Total cost of food, transport per council meeting | E22: =Cover!$B$4&"/meeting" -> EUR/meeting | G22: 3000
B23: > How many farmers will the Lead Farmers represent | E23: # | G23: 100
A24: Baseline surveys | B24: Cost for performing a survey | E24: =Cover!$B$4 -> EUR | G24: =2*G9 -> 20
A25: Annual reporting | B25: Cost of annual reporting (on average 2 days) | E25: =Cover!$B$4 -> EUR | G25: =16*G9 -> 160
A28: Number of participating farmers | B28: For reference only | G28: ='Assumptions (year)'!E3 -> 45170 | H28: ='Assumptions (year)'!F3 -> 45536 | I28: ='Assumptions (year)'!G3 -> 45901 | J28: ='Assumptions (year)'!H3 -> 46266 | K28: ='Assumptions (year)'!I3 -> 46631 | L28: ='Assumptions (year)'!J3 -> 46997
B29: Number of NEW participating farmers to the project over the years | G29: ='Assumptions (year)'!E5 -> 1808.3183 | H29: ='Assumptions (year)'!F5 -> 3616.6365 | I29: ='Assumptions (year)'!G5 -> 5424.9548 | J29: ='Assumptions (year)'!H5 -> 5424.9548 | K29: ='Assumptions (year)'!I5 -> 5424.9548 | L29: ='Assumptions (year)'!J5 -> 5424.9548
B30: Total number of farmers | G30: =G29 -> 1808.3183 | H30: =G30+H29 -> 5424.9548 | I30: =H30+I29 -> 10849.91 | J30: =I30+J29 -> 16274.864 | K30: =J30+K29 -> 21699.819 | L30: =K30+L29 -> 27124.774
B31: How many enumerators will be hired for each year? | G31: =G18 -> 30 | H31: 30 | I31: 30 | J31: 30 | K31: 30 | L31: 30
B32: How many devices will the team of enumerators need? (Additional to previous year!) | G32: 50 | H32: 50 | I32: 50 | J32: 50 | K32: 50 | L32: 50
B33: Number of days for data collection; sanity check for planning purposes | G33: =IFERROR(G29/(G31*$G$16),"") -> 10.046213 | H33: =IFERROR(H29/(H31*$G$16),"") -> 20.092425 | I33: =IFERROR(I29/(I31*$G$16),"") -> 30.138638 | J33: =IFERROR(J29/(J31*$G$16),"") -> 30.138638 | K33: =IFERROR(K29/(K31*$G$16),"") -> 30.138638 | L33: =IFERROR(L29/(L31*$G$16),"") -> 30.138638
A35: Cost item | B35: Description | E35: Unit | F35: Salary | G35: Number of of employees
A36: Aditional staff costs due to the Acorn project (field officers, technical staff, agronomists etc.) | G36: ='Assumptions (year)'!E$3 -> 45170 | H36: ='Assumptions (year)'!F$3 -> 45536 | I36: ='Assumptions (year)'!G$3 -> 45901 | J36: ='Assumptions (year)'!H$3 -> 46266 | K36: ='Assumptions (year)'!I$3 -> 46631 | L36: ='Assumptions (year)'!J$3 -> 46997 | M36: ='Assumptions (year)'!K$3 -> 47362 | N36: ='Assumptions (year)'!L$3 -> 47727 | ... AA36: ='Assumptions (year)'!Y$3 -> 52475
A37: Seniour Management | B37: Country Manager, Director of Reforestation Operations, CFO, Director of HR, Director of Partnership&ITC, Managers | E37: =Cover!$B$4&"/year" -> EUR/year | F37: 23000 | G37: 9 | H37: 13 | I37: 17 | J37: 17 | K37: 17 | L37: 17 | M37: 17 | N37: 17 | O37: 17 | P37: 17 | Q37: 17 | R37: 8 | S37: 8 | T37: 8 | U37: 8 | V37: 8 | W37: 8 | X37: 8 | Y37: 8
A38: Technical Staff | B38: Technical Staff, Forest Engineer, Employees, Executive Secretary, Secretaries, Accountant | E38: =Cover!$B$4&"/year" -> EUR/year | F38: 8000 | G38: 19 | H38: 37 | I38: 55 | J38: 55 | K38: 55 | L38: 55 | M38: 55 | N38: 55 | O38: 55 | P38: 55 | Q38: 55 | R38: 10 | S38: 10 | T38: 10 | U38: 10 | V38: 10 | W38: 10 | X38: 10 | Y38: 10
A39: Nursery Staff | B39: Trainees/Students, Drivers, Field Agent, Maintenance Personnel, Security | E39: =Cover!$B$4&"/year" -> EUR/year | F39: 3000 | G39: 60 | H39: 120 | I39: 180 | J39: 180 | K39: 180 | L39: 180 | M39: 180 | N39: 180 | O39: 180 | P39: 180 | Q39: 180 | R39: 43 | S39: 43 | T39: 43 | U39: 43 | V39: 43 | W39: 43 | X39: 43 | Y39: 43
A41: Please add underlying calculations and/or explain assumptions below
A42: %75 percent of Project Council Costs and Farmer engagement costs will be going to the farmers

Sheet Output Farmer
A1: Output - Farmer
A2: Timing
A3: Program year | E3: ='Assumptions (year)'!E2 -> 0 | F3: ='Assumptions (year)'!F2 -> 1 | G3: ='Assumptions (year)'!G2 -> 2 | H3: ='Assumptions (year)'!H2 -> 3 | I3: ='Assumptions (year)'!I2 -> 4 | J3: ='Assumptions (year)'!J2 -> 5 | K3: ='Assumptions (year)'!K2 -> 6 | L3: ='Assumptions (year)'!L2 -> 7 | ... Y3: ='Assumptions (year)'!Y2 -> 20
A4: Year | E4: ='Assumptions (year)'!E3 -> 45170 | F4: ='Assumptions (year)'!F3 -> 45536 | G4: ='Assumptions (year)'!G3 -> 45901 | H4: ='Assumptions (year)'!H3 -> 46266 | I4: ='Assumptions (year)'!I3 -> 46631 | J4: ='Assumptions (year)'!J3 -> 46997 | K4: ='Assumptions (year)'!K3 -> 47362 | L4: ='Assumptions (year)'!L3 -> 47727 | ... Y4: ='Assumptions (year)'!Y3 -> 52475
A5: Baseline
A6: Average land per farmer (ha) | E6: =Assumptions!$D$5 -> 1 | F6: =Assumptions!$D$5 -> 1 | G6: =Assumptions!$D$5 -> 1 | H6: =Assumptions!$D$5 -> 1 | I6: =Assumptions!$D$5 -> 1 | J6: =Assumptions!$D$5 -> 1 | K6: =Assumptions!$D$5 -> 1 | L6: =Assumptions!$D$5 -> 1 | ... Y6: =Assumptions!$D$5 -> 1
A7: Total revenues (EUR) | E7: =E6*Cover!$B$5*SUMPRODUCT(Assumptions!$H$6:$H$10,Assumptions!$I$6:$I$10) -> 800 | F7: =F6*Cover!$B$5*SUMPRODUCT(Assumptions!$H$6:$H$10,Assumptions!$I$6:$I$10) -> 800 | G7: =G6*Cover!$B$5*SUMPRODUCT(Assumptions!$H$6:$H$10,Assumptions!$I$6:$I$10) -> 800 | H7: =H6*Cover!$B$5*SUMPRODUCT(Assumptions!$H$6:$H$10,Assumptions!$I$6:$I$10) -> 800 | I7: =I6*Cover!$B$5*SUMPRODUCT(Assumptions!$H$6:$H$10,Assumptions!$I$6:$I$10) -> 800 | J7: =J6*Cover!$B$5*SUMPRODUCT(Assumptions!$H$6:$H$10,Assumptions!$I$6:$I$10) -> 800 | K7: =K6*Cover!$B$5*SUMPRODUCT(Assumptions!$H$6:$H$10,Assumptions!$I$6:$I$10) -> 800 | L7: =L6*Cover!$B$5*SUMPRODUCT(Assumptions!$H$6:$H$10,Assumptions!$I$6:$I$10) -> 800 | ... Y7: =Y6*Cover!$B$5*SUMPRODUCT(Assumptions!$H$6:$H$10,Assumptions!$I$6:$I$10) -> 800
A8: Total costs (EUR) | E8: =E6*-SUM(Assumptions!$J$6:$J$10)*Cover!$B$5 -> -800 | F8: =F6*-SUM(Assumptions!$J$6:$J$10)*Cover!$B$5 -> -800 | G8: =G6*-SUM(Assumptions!$J$6:$J$10)*Cover!$B$5 -> -800 | H8: =H6*-SUM(Assumptions!$J$6:$J$10)*Cover!$B$5 -> -800 | I8: =I6*-SUM(Assumptions!$J$6:$J$10)*Cover!$B$5 -> -800 | J8: =J6*-SUM(Assumptions!$J$6:$J$10)*Cover!$B$5 -> -800 | K8: =K6*-SUM(Assumptions!$J$6:$J$10)*Cover!$B$5 -> -800 | L8: =L6*-SUM(Assumptions!$J$6:$J$10)*Cover!$B$5 -> -800 | ... Y8: =Y6*-SUM(Assumptions!$J$6:$J$10)*Cover!$B$5 -> -800
A9: Baseline profit | E9: =E7+E8 -> 0 | F9: =F7+F8 -> 0 | G9: =G7+G8 -> 0 | H9: =H7+H8 -> 0 | I9: =I7+I8 -> 0 | J9: =J7+J8 -> 0 | K9: =K7+K8 -> 0 | L9: =L7+L8 -> 0 | ... Y9: =Y7+Y8 -> 0
A10: Transition costs & benefits | D10: Total
A11: Input | B11: Unit | C11: Cash/non-cash
A12: # new seedlings | B12: ha | E12: =SUM(Assumptions!H21:H25) -> 583 | F12: =SUM(Assumptions!I21:I25) -> 0 | G12: =SUM(Assumptions!J21:J25) -> 0 | H12: 0 | I12: =H12 -> 0 | J12: =I12 -> 0 | K12: =J12 -> 0 | L12: =K12 -> 0 | M12: =L12 -> 0 | N12: =M12 -> 0 | O12: =N12 -> 0 | P12: =O12 -> 0 | ... Y12: =X12 -> 0
A13: Seedling costs | B13: EUR/ha | C13: Cash | E13: =SUMPRODUCT(Assumptions!H21:H25,Assumptions!$K21:$K25)*Cover!$B$5 -> 349.8 | F13: =(Assumptions!$I$21*Assumptions!$K$21)+(Assumptions!$I$22*Assumptions!$K$22)+(Assumptions!$I$23*Assumptions!$K$23)+(Assumptions!$I$24*Assumptions!$K$24)+(Assumptions!$I$25*Assumptions!$K$25)*Cover!$B$5 -> 0 | G13: =(Assumptions!$J$21*Assumptions!$K$21)+(Assumptions!$J$22*Assumptions!$K$22)+(Assumptions!$J$23*Assumptions!$K$23)+(Assumptions!$J$24*Assumptions!$J$24)+(Assumptions!$J$25*Assumptions!$K$25)*Cover!$B$5 -> 0 | H13: 0 | I13: 0 | J13: 0 | K13: 0 | L13: 0 | M13: 0 | N13: 0 | O13: 0 | P13: 0 | Q13: 0 | R13: 0 | S13: 0 | T13: 0 | U13: 0 | V13: 0 | W13: 0 | X13: 0 | Y13: 0
A14: Seedling costs | B14: EUR | C14: Cash | E14: =E13*E6 -> 349.8 | F14: =F13*F6 -> 0 | G14: =G13*G6 -> 0 | H14: =H13*H6 -> 0 | I14: =I13*I6 -> 0 | J14: =J13*J6 -> 0 | K14: =K13*K6 -> 0 | L14: =L13*L6 -> 0 | ... Y14: =Y13*Y6 -> 0
A15: Tree planting costs | B15: EUR | C15: Cash | E15: =('Budget Farmer'!E15*'Output Farmer'!$E$6)*Cover!$B$5 -> 204.05 | F15: =('Budget Farmer'!F15*'Output Farmer'!$E$6)*Cover!$B$5 -> 204.05 | G15: =('Budget Farmer'!G15*'Output Farmer'!$E$6)*Cover!$B$5 -> 204.05 | H15: =('Budget Farmer'!H15*'Output Farmer'!$E$6)*Cover!$B$5 -> 204.05 | I15: =('Budget Farmer'!I15*'Output Farmer'!$E$6)*Cover!$B$5 -> 204.05 | J15: =('Budget Farmer'!J15*'Output Farmer'!$E$6)*Cover!$B$5 -> 204.05 | K15: =('Budget Farmer'!K15*'Output Farmer'!$E$6)*Cover!$B$5 -> 0 | L15: =('Budget Farmer'!L15*'Output Farmer'!$E$6)*Cover!$B$5 -> 0 | ... Y15: =('Budget Farmer'!Y15*'Output Farmer'!$E$6)*Cover!$B$5 -> 0
A16: Training costs | B16: EUR | C16: Cash | E16: =IFERROR('Budget Farmer'!E19*Cover!$B$5,"-") -> 3.191875 | F16: =IFERROR('Budget Farmer'!F19*Cover!$B$5,"-") -> 3.3514687 | G16: =IFERROR('Budget Farmer'!G19*Cover!$B$5,"-") -> 3.5190422 | H16: =IFERROR('Budget Farmer'!H19*Cover!$B$5,"-") -> - | I16: =IFERROR('Budget Farmer'!I19*Cover!$B$5,"-") -> - | J16: =IFERROR('Budget Farmer'!J19*Cover!$B$5,"-") -> - | K16: ='Budget Farmer'!K19*Cover!$B$5 -> 0 | L16: ='Budget Farmer'!L19*Cover!$B$5 -> 0 | M16: ='Budget Farmer'!M19*Cover!$B$5 -> 0 | N16: ='Budget Farmer'!N19*Cover!$B$5 -> 0 | O16: ='Budget Farmer'!O19*Cover!$B$5 -> 0 | P16: ='Budget Farmer'!P19*Cover!$B$5 -> 0 | Q16: ='Budget Farmer'!Q19*Cover!$B$5 -> 0 | R16: ='Budget Farmer'!R19*Cover!$B$5 -> 0 | ... Y16: ='Budget Farmer'!Y19*Cover!$B$5 -> 0
A17: Maintenance costs | B17: EUR | C17: Non cash | E17: =Assumptions!$D$8*'Output Farmer'!E6*Cover!$B$5 -> 0 | F17: =Assumptions!$D$8*'Output Farmer'!F6*Cover!$B$5 -> 0 | G17: =Assumptions!$D$8*'Output Farmer'!G6*Cover!$B$5 -> 0 | H17: =Assumptions!$D$8*'Output Farmer'!H6*Cover!$B$5 -> 0 | I17: =Assumptions!$D$8*'Output Farmer'!I6*Cover!$B$5 -> 0 | J17: =Assumptions!$D$8*'Output Farmer'!J6*Cover!$B$5 -> 0 | K17: =Assumptions!$D$8*'Output Farmer'!K6*Cover!$B$5 -> 0 | L17: =Assumptions!$D$8*'Output Farmer'!L6*Cover!$B$5 -> 0 | ... Y17: =Assumptions!$D$8*'Output Farmer'!Y6*Cover!$B$5 -> 0
A18: CRU-payout costs | B18: EUR | C18: Cash | E18: =IF(E39<1,0,('Budget Farmer'!$E$24*Cover!$B$5)) -> 0 | F18: =IF(F39<1,0,('Budget Farmer'!$E$24*Cover!$B$5)) -> 0 | G18: =IF(G39<1,0,('Budget Farmer'!$E$24*Cover!$B$5)) -> 0 | H18: =IF(H39<1,0,('Budget Farmer'!$E$24*Cover!$B$5)) -> 0 | I18: =IF(I39<1,0,('Budget Farmer'!$E$24*Cover!$B$5)) -> 0 | J18: =IF(J39<1,0,('Budget Farmer'!$E$24*Cover!$B$5)) -> 0 | K18: =IF(K39<1,0,('Budget Farmer'!$E$24*Cover!$B$5)) -> 0 | L18: =IF(L39<1,0,('Budget Farmer'!$E$24*Cover!$B$5)) -> 0 | ... Y18: =IF(Y39<1,0,('Budget Farmer'!$E$24*Cover!$B$5)) -> 0
A19: Total transition costs | B19: EUR | C19: Cash and non cash | E19: =SUM(E14:E18) -> 557.04188 | F19: =SUM(F14:F18) -> 207.40147 | G19: =SUM(G14:G18) -> 207.56904 | H19: =SUM(H14:H18) -> 204.05 | I19: =SUM(I14:I18) -> 204.05 | J19: =SUM(J14:J18) -> 204.05 | K19: =SUM(K14:K18) -> 0 | L19: =SUM(L14:L18) -> 0 | ... Y19: =SUM(Y14:Y18) -> 0
A20: Total transition costs | B20: EUR | C20: Cash only | E20: =IFERROR(E14+E15+E16+E18,"-") -> 557.04188 | F20: =IFERROR(F14+F15+F16+F18,"-") -> 207.40147 | G20: =IFERROR(G14+G15+G16+G18,"-") -> 207.56904 | H20: =IFERROR(H14+H15+H16+H18,"-") -> - | I20: =IFERROR(I14+I15+I16+I18,"-") -> - | J20: =IFERROR(J14+J15+J16+J18,"-") -> - | K20: =IFERROR(K14+K15+K16+K18,"-") -> 0 | L20: =IFERROR(L14+L15+L16+L18,"-") -> 0 | ... Y20: =IFERROR(Y14+Y15+Y16+Y18,"-") -> 0
A21: Total transition costs | E21: =E20*-1 -> -557.04188 | F21: =F20*-1 -> -207.40147 | G21: =G20*-1 -> -207.56904 | H21: =H20*-1 -> #VALUE! | I21: =I20*-1 -> #VALUE! | J21: =J20*-1 -> #VALUE! | K21: =K20*-1 -> 0 | L21: =L20*-1 -> 0 | ... Y21: =Y20*-1 -> 0
A23: Transition impact on current crops
A24: Change in crop revenue due to productivity change | B24: EUR | E24: =E6*('Assumptions (year)'!E9*(Assumptions!$H$6*Assumptions!$I$6)+'Assumptions (year)'!E13*(Assumptions!$H$7*Assumptions!$I$7)+'Assumptions (year)'!E17*(Assumptions!$H$8*Assumptions!$I$8)+'Assumptions (year)'!E21*(Assumptions!$H$9*Assumptions!$I$9)+'Assumptions (year)'!E25*(Assumptions!$H$10*Assumptions!$I$10))*Cover!$B$5 -> -40 | F24: =F6*('Assumptions (year)'!F9*(Assumptions!$H$6*Assumptions!$I$6)+'Assumptions (year)'!F13*(Assumptions!$H$7*Assumptions!$I$7)+'Assumptions (year)'!F17*(Assumptions!$H$8*Assumptions!$I$8)+'Assumptions (year)'!F21*(Assumptions!$H$9*Assumptions!$I$9)+'Assumptions (year)'!F25*(Assumptions!$H$10*Assumptions!$I$10))*Cover!$B$5 -> 0 | G24: =G6*('Assumptions (year)'!G9*(Assumptions!$H$6*Assumptions!$I$6)+'Assumptions (year)'!G13*(Assumptions!$H$7*Assumptions!$I$7)+'Assumptions (year)'!G17*(Assumptions!$H$8*Assumptions!$I$8)+'Assumptions (year)'!G21*(Assumptions!$H$9*Assumptions!$I$9)+'Assumptions (year)'!G25*(Assumptions!$H$10*Assumptions!$I$10))*Cover!$B$5 -> 40 | H24: =H6*('Assumptions (year)'!H9*(Assumptions!$H$6*Assumptions!$I$6)+'Assumptions (year)'!H13*(Assumptions!$H$7*Assumptions!$I$7)+'Assumptions (year)'!H17*(Assumptions!$H$8*Assumptions!$I$8)+'Assumptions (year)'!H21*(Assumptions!$H$9*Assumptions!$I$9)+'Assumptions (year)'!H25*(Assumptions!$H$10*Assumptions!$I$10))*Cover!$B$5 -> 80 | I24: =I6*('Assumptions (year)'!I9*(Assumptions!$H$6*Assumptions!$I$6)+'Assumptions (year)'!I13*(Assumptions!$H$7*Assumptions!$I$7)+'Assumptions (year)'!I17*(Assumptions!$H$8*Assumptions!$I$8)+'Assumptions (year)'!I21*(Assumptions!$H$9*Assumptions!$I$9)+'Assumptions (year)'!I25*(Assumptions!$H$10*Assumptions!$I$10))*Cover!$B$5 -> 120 | J24: =J6*('Assumptions (year)'!J9*(Assumptions!$H$6*Assumptions!$I$6)+'Assumptions (year)'!J13*(Assumptions!$H$7*Assumptions!$I$7)+'Assumptions (year)'!J17*(Assumptions!$H$8*Assumptions!$I$8)+'Assumptions (year)'!J21*(Assumptions!$H$9*Assumptions!$I$9)+'Assumptions (year)'!J25*(Assumptions!$H$10*Assumptions!$I$10))*Cover!$B$5 -> 160 | K24: =J24 -> 160 | L24: =K24 -> 160 | M24: =L24 -> 160 | N24: =M24 -> 160 | O24: =N24 -> 160 | P24: =O24 -> 160 | Q24: =P24 -> 160 | R24: =Q24 -> 160 | ... Y24: =X24 -> 160
A25: Change in crop input costs | B25: EUR | E25: =E6*('Assumptions (year)'!E10*(Assumptions!$J$6)+'Assumptions (year)'!E14*(Assumptions!$J$7)+'Assumptions (year)'!E18*(Assumptions!$J$8)+'Assumptions (year)'!E22*(Assumptions!$J$9)+'Assumptions (year)'!E26*(Assumptions!$J$10))*Cover!$B$5 -> 0 | F25: =F6*('Assumptions (year)'!F10*(Assumptions!$J$6)+'Assumptions (year)'!F14*(Assumptions!$J$7)+'Assumptions (year)'!F18*(Assumptions!$J$8)+'Assumptions (year)'!F22*(Assumptions!$J$9)+'Assumptions (year)'!F26*(Assumptions!$J$10))*Cover!$B$5 -> -40 | G25: =G6*('Assumptions (year)'!G10*(Assumptions!$J$6)+'Assumptions (year)'!G14*(Assumptions!$J$7)+'Assumptions (year)'!G18*(Assumptions!$J$8)+'Assumptions (year)'!G22*(Assumptions!$J$9)+'Assumptions (year)'!G26*(Assumptions!$J$10))*Cover!$B$5 -> -80 | H25: =H6*('Assumptions (year)'!H10*(Assumptions!$J$6)+'Assumptions (year)'!H14*(Assumptions!$J$7)+'Assumptions (year)'!H18*(Assumptions!$J$8)+'Assumptions (year)'!H22*(Assumptions!$J$9)+'Assumptions (year)'!H26*(Assumptions!$J$10))*Cover!$B$5 -> -120 | I25: =I6*('Assumptions (year)'!I10*(Assumptions!$J$6)+'Assumptions (year)'!I14*(Assumptions!$J$7)+'Assumptions (year)'!I18*(Assumptions!$J$8)+'Assumptions (year)'!I22*(Assumptions!$J$9)+'Assumptions (year)'!I26*(Assumptions!$J$10))*Cover!$B$5 -> -160 | J25: =J6*('Assumptions (year)'!J10*(Assumptions!$J$6)+'Assumptions (year)'!J14*(Assumptions!$J$7)+'Assumptions (year)'!J18*(Assumptions!$J$8)+'Assumptions (year)'!J22*(Assumptions!$J$9)+'Assumptions (year)'!J26*(Assumptions!$J$10))*Cover!$B$5 -> -160 | K25: =J25 -> -160 | L25: =K25 -> -160 | M25: =L25 -> -160 | N25: =M25 -> -160 | O25: =N25 -> -160 | P25: =O25 -> -160 | Q25: =P25 -> -160 | R25: =Q25 -> -160 | ... Y25: =X25 -> -160
A27: Additional income trees
A28: Additional yield income | B28: EUR | E28: =E6*(('Assumptions (year)'!E$30*Assumptions!$L$21*'Assumptions (year)'!E$32)+('Assumptions (year)'!E$35*Assumptions!$L$22*'Assumptions (year)'!E$37)+('Assumptions (year)'!E$40*Assumptions!$L$23*'Assumptions (year)'!E$42)+('Assumptions (year)'!E$45*Assumptions!$L$24*'Assumptions (year)'!E$47)+('Assumptions (year)'!E$50*Assumptions!$L$25*'Assumptions (year)'!E$52))*Cover!$B$5 -> 0 | F28: =F6*(('Assumptions (year)'!F$30*Assumptions!$L$21*'Assumptions (year)'!F$32)+('Assumptions (year)'!F$35*Assumptions!$L$22*'Assumptions (year)'!F$37)+('Assumptions (year)'!F$40*Assumptions!$L$23*'Assumptions (year)'!F$42)+('Assumptions (year)'!F$45*Assumptions!$L$24*'Assumptions (year)'!F$47)+('Assumptions (year)'!F$50*Assumptions!$L$25*'Assumptions (year)'!F$52))*Cover!$B$5 -> 40 | G28: =G6*(('Assumptions (year)'!G$30*Assumptions!$L$21*'Assumptions (year)'!G$32)+('Assumptions (year)'!G$35*Assumptions!$L$22*'Assumptions (year)'!G$37)+('Assumptions (year)'!G$40*Assumptions!$L$23*'Assumptions (year)'!G$42)+('Assumptions (year)'!G$45*Assumptions!$L$24*'Assumptions (year)'!G$47)+('Assumptions (year)'!G$50*Assumptions!$L$25*'Assumptions (year)'!G$52))*Cover!$B$5 -> 120 | H28: =H6*(('Assumptions (year)'!H$30*Assumptions!$L$21*'Assumptions (year)'!H$32)+('Assumptions (year)'!H$35*Assumptions!$L$22*'Assumptions (year)'!H$37)+('Assumptions (year)'!H$40*Assumptions!$L$23*'Assumptions (year)'!H$42)+('Assumptions (year)'!H$45*Assumptions!$L$24*'Assumptions (year)'!H$47)+('Assumptions (year)'!H$50*Assumptions!$L$25*'Assumptions (year)'!H$52))*Cover!$B$5 -> 180 | I28: =I6*(('Assumptions (year)'!I$30*Assumptions!$L$21*'Assumptions (year)'!I$32)+('Assumptions (year)'!I$35*Assumptions!$L$22*'Assumptions (year)'!I$37)+('Assumptions (year)'!I$40*Assumptions!$L$23*'Assumptions (year)'!I$42)+('Assumptions (year)'!I$45*Assumptions!$L$24*'Assumptions (year)'!I$47)+('Assumptions (year)'!I$50*Assumptions!$L$25*'Assumptions (year)'!I$52))*Cover!$B$5 -> 240 | J28: =J6*(('Assumptions (year)'!J$30*Assumptions!$L$21*'Assumptions (year)'!J$32)+('Assumptions (year)'!J$35*Assumptions!$L$22*'Assumptions (year)'!J$37)+('Assumptions (year)'!J$40*Assumptions!$L$23*'Assumptions (year)'!J$42)+('Assumptions (year)'!J$45*Assumptions!$L$24*'Assumptions (year)'!J$47)+('Assumptions (year)'!J$50*Assumptions!$L$25*'Assumptions (year)'!J$52))*Cover!$B$5 -> 380 | K28: =K6*(('Assumptions (year)'!K$30*Assumptions!$L$21*'Assumptions (year)'!K$32)+('Assumptions (year)'!K$35*Assumptions!$L$22*'Assumptions (year)'!K$37)+('Assumptions (year)'!K$40*Assumptions!$L$23*'Assumptions (year)'!K$42)+('Assumptions (year)'!K$45*Assumptions!$L$24*'Assumptions (year)'!K$47)+('Assumptions (year)'!K$50*Assumptions!$L$25*'Assumptions (year)'!K$52))*Cover!$B$5 -> 820 | L28: =L6*(('Assumptions (year)'!L$30*Assumptions!$L$21*'Assumptions (year)'!L$32)+('Assumptions (year)'!L$35*Assumptions!$L$22*'Assumptions (year)'!L$37)+('Assumptions (year)'!L$40*Assumptions!$L$23*'Assumptions (year)'!L$42)+('Assumptions (year)'!L$45*Assumptions!$L$24*'Assumptions (year)'!L$47)+('Assumptions (year)'!L$50*Assumptions!$L$25*'Assumptions (year)'!L$52))*Cover!$B$5 -> 1260 | ... Y28: =Y6*(('Assumptions (year)'!Y$30*Assumptions!$L$21*'Assumptions (year)'!Y$32)+('Assumptions (year)'!Y$35*Assumptions!$L$22*'Assumptions (year)'!Y$37)+('Assumptions (year)'!Y$40*Assumptions!$L$23*'Assumptions (year)'!Y$42)+('Assumptions (year)'!Y$45*Assumptions!$L$24*'Assumptions (year)'!Y$47)+('Assumptions (year)'!Y$50*Assumptions!$L$25*'Assumptions (year)'!Y$52))*Cover!$B$5 -> 8500
A29: Agroforestry impact on baseline | B29: EUR | D29: =SUM(E29:Y29) -> 72795.838 | E29: =-E19+E24+E25+E28 -> -597.04188 | F29: =-F19+F24+F25+F28 -> -207.40147 | G29: =-G19+G24+G25+G28 -> -127.56904 | H29: =-H19+H24+H25+H28 -> -64.05 | I29: =-I19+I24+I25+I28 -> -4.05 | J29: =-J19+J24+J25+J28 -> 175.95 | K29: =-K19+K24+K25+K28 -> 820 | L29: =-L19+L24+L25+L28 -> 1260 | ... Y29: =-Y19+Y24+Y25+Y28 -> 8500
A30: Expected carbon sequestration benefits | D30: Total
A31: Number of surviving trees | B31: # | E31: =('Assumptions (year)'!E32+'Assumptions (year)'!E37+'Assumptions (year)'!E42+'Assumptions (year)'!E47+'Assumptions (year)'!E52)*E6 -> 466 | F31: =('Assumptions (year)'!F32+'Assumptions (year)'!F37+'Assumptions (year)'!F42+'Assumptions (year)'!F47+'Assumptions (year)'!F52)*F6 -> 466 | G31: =('Assumptions (year)'!G32+'Assumptions (year)'!G37+'Assumptions (year)'!G42+'Assumptions (year)'!G47+'Assumptions (year)'!G52)*G6 -> 466 | H31: =('Assumptions (year)'!H32+'Assumptions (year)'!H37+'Assumptions (year)'!H42+'Assumptions (year)'!H47+'Assumptions (year)'!H52)*H6 -> 466 | I31: =('Assumptions (year)'!I32+'Assumptions (year)'!I37+'Assumptions (year)'!I42+'Assumptions (year)'!I47+'Assumptions (year)'!I52)*I6 -> 466 | J31: =('Assumptions (year)'!J32+'Assumptions (year)'!J37+'Assumptions (year)'!J42+'Assumptions (year)'!J47+'Assumptions (year)'!J52)*J6 -> 466 | K31: =('Assumptions (year)'!K32+'Assumptions (year)'!K37+'Assumptions (year)'!K42+'Assumptions (year)'!K47+'Assumptions (year)'!K52)*K6 -> 466 | L31: =('Assumptions (year)'!L32+'Assumptions (year)'!L37+'Assumptions (year)'!L42+'Assumptions (year)'!L47+'Assumptions (year)'!L52)*L6 -> 466 | ... Y31: =('Assumptions (year)'!Y32+'Assumptions (year)'!Y37+'Assumptions (year)'!Y42+'Assumptions (year)'!Y47+'Assumptions (year)'!Y52)*Y6 -> 466
A32: Expected annual CO2 sequestered for all trees | B32: kg | E32: ='Assumptions (year)'!E66*E6 -> 0 | F32: ='Assumptions (year)'!F66*F6 -> 0 | G32: ='Assumptions (year)'!G66*G6 -> 0 | H32: ='Assumptions (year)'!H66*H6 -> 0 | I32: ='Assumptions (year)'!I66*I6 -> 0 | J32: ='Assumptions (year)'!J66*J6 -> 0 | K32: ='Assumptions (year)'!K66*K6 -> 0 | L32: ='Assumptions (year)'!L66*L6 -> 0 | ... Y32: ='Assumptions (year)'!Y66*Y6 -> 0
A33: Expected annual CO2 sequestered for all trees | B33: kg (tonnes) | E33: =E32/1000 -> 0 | F33: =F32/1000 -> 0 | G33: =G32/1000 -> 0 | H33: =H32/1000 -> 0 | I33: =I32/1000 -> 0 | J33: =J32/1000 -> 0 | K33: =K32/1000 -> 0 | L33: =L32/1000 -> 0 | ... Y33: =Y32/1000 -> 0
A34: CO2 - part stored in Buffer Pool | B34: kg (tonnes) | E34: =Assumptions!$D$23*'Output Farmer'!E33 -> 0 | F34: =Assumptions!$D$23*'Output Farmer'!F33 -> 0 | G34: =Assumptions!$D$23*'Output Farmer'!G33 -> 0 | H34: =Assumptions!$D$23*'Output Farmer'!H33 -> 0 | I34: =Assumptions!$D$23*'Output Farmer'!I33 -> 0 | J34: =Assumptions!$D$23*'Output Farmer'!J33 -> 0 | K34: =Assumptions!$D$23*'Output Farmer'!K33 -> 0 | L34: =Assumptions!$D$23*'Output Farmer'!L33 -> 0 | ... Y34: =Assumptions!$D$23*'Output Farmer'!Y33 -> 0
A35: Net CRUs (minus buffer pool + partial CRUs from prior year) | B35: # | E35: =(E33-E34+C36)*Assumptions!$D$24 -> 0 | F35: =(F33-F34+E36)*Assumptions!$D$24 -> 0 | G35: =(G33-G34+F36)*Assumptions!$D$24 -> 0 | H35: =(H33-H34+G36)*Assumptions!$D$24 -> 0 | I35: =(I33-I34+H36)*Assumptions!$D$24 -> 0 | J35: =(J33-J34+I36)*Assumptions!$D$24 -> 0 | K35: =(K33-K34+J36)*Assumptions!$D$24 -> 0 | L35: =(L33-L34+K36)*Assumptions!$D$24 -> 0 | M35: =(M33-M34+L36)*Assumptions!$D$24 -> 0 | ... Y35: =(Y33-Y34+X36)*Assumptions!$D$24 -> 0
A36: Part of CRUs moved to next year | B36: # | E36: =E35-E37 -> 0 | F36: =F35-F37 -> 0 | G36: =G35-G37 -> 0 | H36: =H35-H37 -> 0 | I36: =I35-I37 -> 0 | J36: =J35-J37 -> 0 | K36: =K35-K37 -> 0 | L36: =L35-L37 -> 0 | ... Y36: =Y35-Y37 -> 0
A37: CRUs per farmer (rounded down) | B37: # | D37: =SUM(E37:Y37) -> 0 | E37: =ROUNDDOWN(E35,0) -> 0 | F37: =ROUNDDOWN(F35,0) -> 0 | G37: =ROUNDDOWN(G35,0) -> 0 | H37: =ROUNDDOWN(H35,0) -> 0 | I37: =ROUNDDOWN(I35,0) -> 0 | J37: =ROUNDDOWN(J35,0) -> 0 | K37: =ROUNDDOWN(K35,0) -> 0 | L37: =ROUNDDOWN(L35,0) -> 0 | ... Y37: =ROUNDDOWN(Y35,0) -> 0
A38: Total CRU revenue | B38: EUR | D38: =SUM(E38:Y38) -> 0 | E38: =E$37*Assumptions!$D$19 -> 0 | F38: =F$37*Assumptions!$D$19 -> 0 | G38: =G$37*Assumptions!$D$19 -> 0 | H38: =H$37*Assumptions!$D$19 -> 0 | I38: =I$37*Assumptions!$D$19 -> 0 | J38: =J$37*Assumptions!$D$19 -> 0 | K38: =K$37*Assumptions!$D$19 -> 0 | L38: =L$37*Assumptions!$D$19 -> 0 | ... Y38: =Y$37*Assumptions!$D$19 -> 0
A39: CRU revenue - farmer | B39: EUR | D39: =SUM(E39:Y39) -> 0 | E39: =Assumptions!$D$20*'Output Farmer'!E$38 -> 0 | F39: =Assumptions!$D$20*'Output Farmer'!F$38 -> 0 | G39: =Assumptions!$D$20*'Output Farmer'!G$38 -> 0 | H39: =Assumptions!$D$20*'Output Farmer'!H$38 -> 0 | I39: =Assumptions!$D$20*'Output Farmer'!I$38 -> 0 | J39: =Assumptions!$D$20*'Output Farmer'!J$38 -> 0 | K39: =Assumptions!$D$20*'Output Farmer'!K$38 -> 0 | L39: =Assumptions!$D$20*'Output Farmer'!L$38 -> 0 | ... Y39: =Assumptions!$D$20*'Output Farmer'!Y$38 -> 0
A40: CRU revenue in cash | B40: EUR | D40: =SUM(E40:Y40) -> 0 | E40: =IF(Finance!E19>0,Finance!E$12,'Output Farmer'!E$39) -> 0 | F40: =IF(Finance!F19>0,Finance!F$12,'Output Farmer'!F$39) -> 0 | G40: =IF(Finance!G19>0,Finance!G$12,'Output Farmer'!G$39) -> 0 | H40: =IF(Finance!H19>0,Finance!H$12,'Output Farmer'!H$39) -> 0 | I40: =IF(Finance!I19>0,Finance!I$12,'Output Farmer'!I$39) -> 0 | J40: =IF(Finance!J19>0,Finance!J$12,'Output Farmer'!J$39) -> 0 | K40: =IF(Finance!K19>0,Finance!K$12,'Output Farmer'!K$39) -> 0 | L40: =IF(Finance!L19>0,Finance!L$12,'Output Farmer'!L$39) -> 0 | ... Y40: =IF(Finance!Y19>0,Finance!Y$12,'Output Farmer'!Y$39) -> 0
A41: CRU revenue used for debt service (repayment + interest) | B41: EUR | D41: =SUM(E41:Y41) -> 0 | E41: =E39-E40 -> 0 | F41: =F39-F40 -> 0 | G41: =G39-G40 -> 0 | H41: =H39-H40 -> 0 | I41: =I39-I40 -> 0 | J41: =J39-J40 -> 0 | K41: =K39-K40 -> 0 | L41: =L39-L40 -> 0 | ... Y41: =Y39-Y40 -> 0
A43: Impact indicators | D43: Total
...

Sheet Output LP
A1: Output - Local Partner
A2: Program year | E2: ='Assumptions (year)'!E2 -> 0 | F2: ='Assumptions (year)'!F2 -> 1 | G2: ='Assumptions (year)'!G2 -> 2 | H2: ='Assumptions (year)'!H2 -> 3 | I2: ='Assumptions (year)'!I2 -> 4 | J2: ='Assumptions (year)'!J2 -> 5 | K2: ='Assumptions (year)'!K2 -> 6 | L2: ='Assumptions (year)'!L2 -> 7 | ... Y2: ='Assumptions (year)'!Y2 -> 20
A3: Year | E3: ='Assumptions (year)'!E3 -> 45170 | F3: ='Assumptions (year)'!F3 -> 45536 | G3: ='Assumptions (year)'!G3 -> 45901 | H3: ='Assumptions (year)'!H3 -> 46266 | I3: ='Assumptions (year)'!I3 -> 46631 | J3: ='Assumptions (year)'!J3 -> 46997 | K3: ='Assumptions (year)'!K3 -> 47362 | L3: ='Assumptions (year)'!L3 -> 47727 | ... Y3: ='Assumptions (year)'!Y3 -> 52475
A5: Number of participating farmers | B5: Unit
A6: # of new farmers | B6: # | E6: ='Assumptions (year)'!E$5 -> 1808.3183 | F6: ='Assumptions (year)'!F$5 -> 3616.6365 | G6: ='Assumptions (year)'!G$5 -> 5424.9548 | H6: ='Assumptions (year)'!H$5 -> 5424.9548 | I6: ='Assumptions (year)'!I$5 -> 5424.9548 | J6: ='Assumptions (year)'!J$5 -> 5424.9548 | K6: ='Assumptions (year)'!K$5 -> 0 | L6: ='Assumptions (year)'!L$5 -> 0 | ... Y6: ='Assumptions (year)'!Y$5 -> 0
A7: total number of farmers | B7: # | E7: =E6+C7 -> 1808.3183 | F7: =F6+E7 -> 5424.9548 | G7: =G6+F7 -> 10849.91 | H7: =H6+G7 -> 16274.864 | I7: =I6+H7 -> 21699.819 | J7: =J6+I7 -> 27124.774 | K7: =K6+J7 -> 27124.774 | L7: =L6+K7 -> 27124.774 | M7: =M6+L7 -> 27124.774 | ... Y7: =Y6+X7 -> 27124.774
A9: Revenues Local Partner | B9: Unit | C9: Total
A10: CRU Revenue | B10: EUR | C10: =SUM(E10:Y10) -> 0 | E10: ='Output Project '!E$62 -> 0 | F10: ='Output Project '!F$62 -> 0 | G10: ='Output Project '!G$62 -> 0 | H10: ='Output Project '!H$62 -> 0 | I10: ='Output Project '!I$62 -> 0 | J10: ='Output Project '!J$62 -> 0 | K10: ='Output Project '!K$62 -> 0 | L10: ='Output Project '!L$62 -> 0 | ... Y10: ='Output Project '!Y$62 -> 0
A11: Total | B11: EUR | C11: =SUM(E11:Y11) -> 0 | E11: =SUM(E10:E10) -> 0 | F11: =SUM(F10:F10) -> 0 | G11: =SUM(G10:G10) -> 0 | H11: =SUM(H10:H10) -> 0 | I11: =SUM(I10:I10) -> 0 | J11: =SUM(J10:J10) -> 0 | K11: =SUM(K10:K10) -> 0 | L11: =SUM(L10:L10) -> 0 | ... Y11: =SUM(Y10:Y10) -> 0
A13: Costs Local Partner | B13: Unit | C13: Total
A14: One off project cost | B14: EUR | C14: =SUM(E14:Y14) -> 50920 | E14: =('Budget LP'!G7+'Budget LP'!G8)*Cover!$B$5 -> 50920
A15: Farmer engagement cost | B15: EUR | C15: =SUM(E15:Y15) -> 1342676.3 | E15: =E6*('Budget LP'!$G$10+'Budget LP'!$G$14)*Cover!$B$5 -> 89511.754 | F15: =F6*('Budget LP'!$G$10+'Budget LP'!$G$14)*Cover!$B$5 -> 179023.51 | G15: =G6*('Budget LP'!$G$10+'Budget LP'!$G$14)*Cover!$B$5 -> 268535.26 | H15: =H6*('Budget LP'!$G$10+'Budget LP'!$G$14)*Cover!$B$5 -> 268535.26 | I15: =I6*('Budget LP'!$G$10+'Budget LP'!$G$14)*Cover!$B$5 -> 268535.26 | J15: =J6*('Budget LP'!$G$10+'Budget LP'!$G$14)*Cover!$B$5 -> 268535.26 | K15: =K6*('Budget LP'!$G$10+'Budget LP'!$G$14)*Cover!$B$5 -> 0 | L15: =L6*('Budget LP'!$G$10+'Budget LP'!$G$14)*Cover!$B$5 -> 0 | ... Y15: =Y6*('Budget LP'!$G$10+'Budget LP'!$G$14)*Cover!$B$5 -> 0
A16: Farmer data collection cost | B16: EUR | C16: =SUM(E16:Y16) -> 226039.78 | E16: =E6*('Budget LP'!$G$15*Cover!$B$5) -> 15069.319 | F16: =F6*('Budget LP'!$G$15*Cover!$B$5) -> 30138.638 | G16: =G6*('Budget LP'!$G$15*Cover!$B$5) -> 45207.957 | H16: =H6*('Budget LP'!$G$15*Cover!$B$5) -> 45207.957 | I16: =I6*('Budget LP'!$G$15*Cover!$B$5) -> 45207.957 | J16: =J6*('Budget LP'!$G$15*Cover!$B$5) -> 45207.957 | K16: =K6*('Budget LP'!$G$15*Cover!$B$5) -> 0 | L16: =L6*('Budget LP'!$G$15*Cover!$B$5) -> 0 | ... Y16: =Y6*('Budget LP'!$G$15*Cover!$B$5) -> 0
A17: Equipment for data collection | B17: EUR | C17: =SUM(E17:Y17) -> 90000 | E17: =('Budget LP'!G32*'Budget LP'!$G$19)*Cover!$B$5 -> 15000 | F17: =('Budget LP'!H32*'Budget LP'!$G$19)*Cover!$B$5 -> 15000 | G17: =('Budget LP'!I32*'Budget LP'!$G$19)*Cover!$B$5 -> 15000 | H17: =('Budget LP'!J32*'Budget LP'!$G$19)*Cover!$B$5 -> 15000 | I17: =('Budget LP'!K32*'Budget LP'!$G$19)*Cover!$B$5 -> 15000 | J17: =('Budget LP'!L32*'Budget LP'!$G$19)*Cover!$B$5 -> 15000 | K17: =('Budget LP'!M32*'Budget LP'!$G$19)*Cover!$B$5 -> 0 | L17: =('Budget LP'!N32*'Budget LP'!$G$19)*Cover!$B$5 -> 0 | ... Y17: =('Budget LP'!AA32*'Budget LP'!$G$19)*Cover!$B$5 -> 0
A18: Project Council cost | B18: EUR | C18: =SUM(E18:Y18) -> 29112134 | E18: =(E7*('Budget LP'!$G$20*Cover!$B$5))*2 -> 107424.85 | F18: =(F7*('Budget LP'!$G$20*Cover!$B$5))*2 -> 322274.54 | G18: =(G7*('Budget LP'!$G$20*Cover!$B$5))*2 -> 644549.08 | H18: =(H7*('Budget LP'!$G$20*Cover!$B$5))*2 -> 966823.63 | I18: =(I7*('Budget LP'!$G$20*Cover!$B$5))*2 -> 1289098.2 | J18: =(J7*('Budget LP'!$G$20*Cover!$B$5))*2 -> 1611372.7 | K18: =(K7*('Budget LP'!$G$20*Cover!$B$5))*2 -> 1611372.7 | L18: =(L7*('Budget LP'!$G$20*Cover!$B$5))*2 -> 1611372.7 | ... Y18: =(Y7*('Budget LP'!$G$20*Cover!$B$5))*2 -> 1611372.7
A19: Additional Staff costs | B19: EUR | C19: =SUM(E19:Y19) -> 16977000 | E19: =(('Budget LP'!$F$37*'Budget LP'!G37)+('Budget LP'!$F$38*'Budget LP'!G38)+('Budget LP'!$F$39*'Budget LP'!G39))*Cover!$B$5 -> 539000 | F19: =(('Budget LP'!$F$37*'Budget LP'!H37)+('Budget LP'!$F$38*'Budget LP'!H38)+('Budget LP'!$F$39*'Budget LP'!H39))*Cover!$B$5 -> 955000 | G19: =(('Budget LP'!$F$37*'Budget LP'!I37)+('Budget LP'!$F$38*'Budget LP'!I38)+('Budget LP'!$F$39*'Budget LP'!I39))*Cover!$B$5 -> 1371000 | H19: =(('Budget LP'!$F$37*'Budget LP'!J37)+('Budget LP'!$F$38*'Budget LP'!J38)+('Budget LP'!$F$39*'Budget LP'!J39))*Cover!$B$5 -> 1371000 | I19: =(('Budget LP'!$F$37*'Budget LP'!K37)+('Budget LP'!$F$38*'Budget LP'!K38)+('Budget LP'!$F$39*'Budget LP'!K39))*Cover!$B$5 -> 1371000 | J19: =(('Budget LP'!$F$37*'Budget LP'!L37)+('Budget LP'!$F$38*'Budget LP'!L38)+('Budget LP'!$F$39*'Budget LP'!L39))*Cover!$B$5 -> 1371000 | K19: =(('Budget LP'!$F$37*'Budget LP'!M37)+('Budget LP'!$F$38*'Budget LP'!M38)+('Budget LP'!$F$39*'Budget LP'!M39))*Cover!$B$5 -> 1371000 | L19: =(('Budget LP'!$F$37*'Budget LP'!N37)+('Budget LP'!$F$38*'Budget LP'!N38)+('Budget LP'!$F$39*'Budget LP'!N39))*Cover!$B$5 -> 1371000 | ... Y19: =(('Budget LP'!$F$37*'Budget LP'!AA37)+('Budget LP'!$F$38*'Budget LP'!AA38)+('Budget LP'!$F$39*'Budget LP'!AA39))*Cover!$B$5 -> 0 | AA19: =('Budget LP'!$F$37*'Budget LP'!AC37)+('Budget LP'!$F$38*'Budget LP'!AC38)+('Budget LP'!$F$39*'Budget LP'!AC39)*Cover!$B$5 -> 0 | AB19: =('Budget LP'!$F$37*'Budget LP'!AD37)+('Budget LP'!$F$38*'Budget LP'!AD38)+('Budget LP'!$F$39*'Budget LP'!AD39)*Cover!$B$5 -> 0 | AC19: =('Budget LP'!$F$37*'Budget LP'!AE37)+('Budget LP'!$F$38*'Budget LP'!AE38)+('Budget LP'!$F$39*'Budget LP'!AE39)*Cover!$B$5 -> 0 | AD19: =('Budget LP'!$F$37*'Budget LP'!AF37)+('Budget LP'!$F$38*'Budget LP'!AF38)+('Budget LP'!$F$39*'Budget LP'!AF39)*Cover!$B$5 -> 0 | AE19: =('Budget LP'!$F$37*'Budget LP'!AG37)+('Budget LP'!$F$38*'Budget LP'!AG38)+('Budget LP'!$F$39*'Budget LP'!AG39)*Cover!$B$5 -> 0 | AF19: =('Budget LP'!$F$37*'Budget LP'!AH37)+('Budget LP'!$F$38*'Budget LP'!AH38)+('Budget LP'!$F$39*'Budget LP'!AH39)*Cover!$B$5 -> 0 | AG19: =('Budget LP'!$F$37*'Budget LP'!AI37)+('Budget LP'!$F$38*'Budget LP'!AI38)+('Budget LP'!$F$39*'Budget LP'!AI39)*Cover!$B$5 -> 0 | AH19: =('Budget LP'!$F$37*'Budget LP'!AJ37)+('Budget LP'!$F$38*'Budget LP'!AJ38)+('Budget LP'!$F$39*'Budget LP'!AJ39)*Cover!$B$5 -> 0 | ... XFB19: =('Budget LP'!$F$37*'Budget LP'!XFD37)+('Budget LP'!$F$38*'Budget LP'!XFD38)+('Budget LP'!$F$39*'Budget LP'!XFD39)*Cover!$B$5 -> 0 | XFC19: =('Budget LP'!$F$37*'Budget LP'!#REF!)+('Budget LP'!$F$38*'Budget LP'!#REF!)+('Budget LP'!$F$39*'Budget LP'!#REF!)*Cover!$B$5 -> #REF! | XFD19: =('Budget LP'!$F$37*'Budget LP'!#REF!)+('Budget LP'!$F$38*'Budget LP'!#REF!)+('Budget LP'!$F$39*'Budget LP'!#REF!)*Cover!$B$5 -> #REF!
A20: Baseline assesment cost | B20: EUR | C20: =SUM(E20:Y20) -> 12600 | E20: =((IF((E7*1%)>100,100,30))*'Budget LP'!$G$24)*Cover!$B$5 -> 600 | H20: =((IF((H7*1%)>100,100,30))*'Budget LP'!$G$24)*Cover!$B$5 -> 2000 | K20: =((IF((K7*1%)>100,100,30))*'Budget LP'!$G$24)*Cover!B5 -> 2000 | N20: =((IF((N7*1%)>100,100,30))*'Budget LP'!$G$24)*Cover!B5 -> 2000 | Q20: =((IF((Q7*1%)>100,100,30))*'Budget LP'!$G$24)*Cover!B5 -> 2000 | T20: =((IF((T7*1%)>100,100,30))*'Budget LP'!$G$24)*Cover!B5 -> 2000 | W20: =((IF((W7*1%)>100,100,30))*'Budget LP'!$G$24)*Cover!B5 -> 2000
A21: Annual reporting cost | B21: EUR | C21: =SUM(E21:Y21) -> 3360 | E21: ='Budget LP'!$G$25*Cover!$B$5 -> 160 | F21: ='Budget LP'!$G$25*Cover!$B$5 -> 160 | G21: ='Budget LP'!$G$25*Cover!$B$5 -> 160 | H21: ='Budget LP'!$G$25*Cover!$B$5 -> 160 | I21: ='Budget LP'!$G$25*Cover!$B$5 -> 160 | J21: ='Budget LP'!$G$25*Cover!$B$5 -> 160 | K21: ='Budget LP'!$G$25*Cover!$B$5 -> 160 | L21: ='Budget LP'!$G$25*Cover!$B$5 -> 160 | ... Y21: ='Budget LP'!$G$25*Cover!$B$5 -> 160
A22: Total Local Partner Costs | B22: EUR | C22: =SUM(E22:Y22) -> 47814730 | E22: =SUM(E14:E21) -> 817685.92 | F22: =SUM(F14:F21) -> 1501596.7 | G22: =SUM(G14:G21) -> 2344452.3 | H22: =SUM(H14:H21) -> 2668726.8 | I22: =SUM(I14:I21) -> 2989001.4 | J22: =SUM(J14:J21) -> 3311275.9 | K22: =SUM(K14:K21) -> 2984532.7 | L22: =SUM(L14:L21) -> 2982532.7 | ... Y22: =SUM(Y14:Y21) -> 1611532.7
A23: Total Local Partner Costs | B23: EUR | C23: =SUM(E23:Y23) -> -47814730 | E23: =E22*-1 -> -817685.92 | F23: =F22*-1 -> -1501596.7 | G23: =G22*-1 -> -2344452.3 | H23: =H22*-1 -> -2668726.8 | I23: =I22*-1 -> -2989001.4 | J23: =J22*-1 -> -3311275.9 | K23: =K22*-1 -> -2984532.7 | L23: =L22*-1 -> -2982532.7 | ... Y23: =Y22*-1 -> -1611532.7
A24: Result Local Partner | B24: Unit | C24: Total
A25: Total result | B25: EUR | C25: =C11-C22 -> -47814730 | E25: =E11-E22 -> -817685.92 | F25: =F11-F22 -> -1501596.7 | G25: =G11-G22 -> -2344452.3 | H25: =H11-H22 -> -2668726.8 | I25: =I11-I22 -> -2989001.4 | J25: =J11-J22 -> -3311275.9 | K25: =K11-K22 -> -2984532.7 | L25: =L11-L22 -> -2982532.7 | ... Y25: =Y11-Y22 -> -1611532.7
A26: Cumulative results | B26: EUR | E26: =E25 -> -817685.92 | F26: =E26+F25 -> -2319282.6 | G26: =F26+G25 -> -4663734.9 | H26: =G26+H25 -> -7332461.8 | I26: =H26+I25 -> -10321463 | J26: =I26+J25 -> -13632739 | K26: =J26+K25 -> -16617272 | L26: =K26+L25 -> -19599804 | M26: =L26+M25 -> -22582337 | ... Y26: =X26+Y25 -> -47814730
A28: Farmer package | B28: Unit | C28: Total
A29: CRU revenue | B29: EUR | C29: =SUM(E29:Y29) -> 0 | E29: ='Output Project '!E61 -> 0 | F29: ='Output Project '!F61 -> 0 | G29: ='Output Project '!G61 -> 0 | H29: ='Output Project '!H61 -> 0 | I29: ='Output Project '!I61 -> 0 | J29: ='Output Project '!J61 -> 0 | K29: ='Output Project '!K61 -> 0 | L29: ='Output Project '!L61 -> 0 | ... Y29: ='Output Project '!Y61 -> 0
A30: Aggregared farmer package | B30: EUR | C30: =SUM(E30:Y30) -> 26365616 | E30: =IFERROR('Output Project '!E18,"-") -> 1007309 | F30: =IFERROR('Output Project '!F18,"-") -> 2389665.9 | G30: =IFERROR('Output Project '!G18,"-") -> 4147373.6 | H30: =IFERROR('Output Project '!H18,"-") -> 4897772.4 | I30: =IFERROR('Output Project '!I18,"-") -> 5273123.3 | J30: =IFERROR('Output Project '!J18,"-") -> 5273123.3 | K30: =IFERROR('Output Project '!K18,"-") -> 2251196.3 | L30: =IFERROR('Output Project '!L18,"-") -> 1126052.7 | ... Y30: =IFERROR('Output Project '!Y18,"-") -> 0
A31: Aggregated result farmers | B31: EUR | C31: =C29-C30 -> -26365616 | E31: =IFERROR(E29-E30,"-") -> -1007309 | F31: =IFERROR(F29-F30,"-") -> -2389665.9 | G31: =IFERROR(G29-G30,"-") -> -4147373.6 | H31: =IFERROR(H29-H30,"-") -> -4897772.4 | I31: =IFERROR(I29-I30,"-") -> -5273123.3 | J31: =IFERROR(J29-J30,"-") -> -5273123.3 | K31: =IFERROR(K29-K30,"-") -> -2251196.3 | L31: =IFERROR(L29-L30,"-") -> -1126052.7 | ... Y31: =IFERROR(Y29-Y30,"-") -> 0
A33: Total investment cost project | B33: Unit | C33: Total
